Workbook
Name EF_APLIC: 'PARAMETROS'!$B$5
Name TURNO: 'PARAMETROS'!$B$6
Name FRAC_ACOMP: 'PARAMETROS'!$B$7
Name DATA_REF: 'PARAMETROS'!$B$8
Name ETO_SEM: 'ETO_SEMANAL'!$B$3
Name CHUVA_SEM: 'ETO_SEMANAL'!$B$2

Sheet LEIA-ME
A1: Manejo de Irrigacao Karitel/RDM - v7
A2: So pivos plantados. ETo semanal. Kc linear por DAE.
B4: SO PLANTADOS: Cada aba de cultura mostra so os pivos JA PLANTADOS (filtro Plantado=SIM). Os nao plantados ficam ocultos.
B5: AVISAR PLANTIO: Para incluir um pivo: preencha a DATA DE PLANTIO real dele na aba da cultura. Ele vira Plantado=SIM. Depois use Dados > Reaplicar (ou abra o filtro da coluna Plantado) para a lista atualizar.
B6: EMERGENCIA: Soja e algodao: DAE = DAP - 5 (5 dias de emergencia). Tabaco/cacau/milho: DAE = DAP.
B7: Kc: Coluna Kc = curva diaria (CURVAS_KC) pelo DAE. Cada aba tem o GRAFICO da curva de Kc da cultura.
B8: SOMA DA ETO: ETo acum = SOMA das ETos semanais (ETO_SEMANAL) desde a Ult.irrig ate hoje. ETc acum = Kc x ETo acum. Nec BRUTA = (ETc acum - chuva)/0,90.
B9: EXECUCAO: Nas parcelas IRRIGAR, digite o % (percentimetro) -> Lamina (mm) e Horas.
B10: ETO / IRRIGAR: Atualize ETO_SEMANAL a cada semana (ETo e chuva). Ao irrigar um pivo, coloque a data em 'Ult.irrig' para zerar a soma e recomecar o acumulo.
B11: MODULOS: Coluna Modulo: M1 (1-34+75,76), M2 (R8-R12), M3 (R13-R18), RDM (101-133). De para filtrar/ordenar por modulo.

Sheet SOJA
A1: SOJA 26/27 - manejo
A2: So pivos PLANTADOS (filtro Plantado=SIM). Avisar plantio = preencher Data plantio. Emergencia 5 dias. ETc=Kc(DAE)xETo semanal.
A4: Pivo | B4: Modulo | C4: Casa b. | D4: Variedade | E4: Classe | F4: Area(ha) | G4: Data plantio | H4: Plantado? | I4: DAP | J4: DAE | K4: Kc | L4: Ult.irrig | M4: ETo acum | N4: Chuva acum | O4: ETc acum | P4: Nec liq (mm) | Q4: Nec BRUTA (mm) | R4: % aplic | S4: Lamina(mm) | T4: Horas | U4: CE(kWh/m3) | V4: Volume(m3) | W4: Energia(kWh) | X4: Decisao | Y4: Prioridade | Z4: Curva Kc | AA4: Cod
A5: Pivô 01 | B5: Modulo 1 | C5: R0 | D5: BMX DOMINIO IPRO | E5: MEDIA | F5: 70 | G5: 46327 | H5: =IF(OR($G5="",$G5>DATA_REF),"NAO","SIM") | I5: =IF(OR($G5="",$G5>DATA_REF),"",DATA_REF-$G5) | J5: =IF($I5="","",MAX(0,$I5-5)) | K5: =IF($Z5="","PENDENTE",IF($I5="","",IFERROR(INDEX(CURVAS_KC!$B$5:$J$224,MATCH(MIN(MAX($J5,1),220),CURVAS_KC!$A$5:$A$224,0),MATCH($Z5,CURVAS_KC!$B$4:$J$4,0)),"PENDENTE"))) | L5: =IF($G5="","",$G5) | M5: =IF($L5="","",SUMIFS(ETO_SEMANAL!$B$6:$B$65,ETO_SEMANAL!$A$6:$A$65,">"&$L5,ETO_SEMANAL!$A$6:$A$65,"<="&DATA_REF)) | N5: =IF($L5="","",SUMIFS(ETO_SEMANAL!$C$6:$C$65,ETO_SEMANAL!$A$6:$A$65,">"&$L5,ETO_SEMANAL!$A$6:$A$65,"<="&DATA_REF)) | O5: =IF(OR($K5="",$K5="PENDENTE",$M5=""),"",$K5*$M5) | P5: =IF($O5="","",MAX(0,$O5-N($N5))) | Q5: =IF($P5="","",$P5/EF_APLIC) | S5: =IF(OR($AA5="",$R5=""),"",IFERROR(INDEX(LAMINA_HORA!$C$5:$V$114,MATCH($AA5,LAMINA_HORA!$A$5:$A$114,0),MATCH($R5,LAMINA_HORA!$C$3:$V$3,0)),"?")) | T5: =IF(OR($AA5="",$R5=""),"",IFERROR(INDEX(LAMINA_HORA!$W$5:$AP$114,MATCH($AA5,LAMINA_HORA!$A$5:$A$114,0),MATCH($R5,LAMINA_HORA!$W$3:$AP$3,0)),"?")) | U5: 0.513 | V5: =IF(OR($S5="",$S5="?",$F5=""),"",$S5*$F5*10) | W5: =IF(OR($V5="",$U5=""),"",$V5*$U5) | X5: =IF($K5="PENDENTE","Definir Kc",IF($P5="","-",IF($P5>=TURNO,"IRRIGAR",IF($P5>=TURNO*FRAC_ACOMP,"Acompanhar","Aguardar")))) | Y5: =IF(OR($P5="",$P5=0),"-",IF($P5>=2*TURNO,"Alta",IF($P5>=TURNO,"Media","Baixa"))) | Z5: SOJA_MEDIA | AA5: P1
A6: Pivô 01 | B6: Modulo 1 | C6: R0 | D6: BMX DOMINIO IPRO | E6: MEDIA | F6: 71 | G6: 46331 | H6: =IF(OR($G6="",$G6>DATA_REF),"NAO","SIM") | I6: =IF(OR($G6="",$G6>DATA_REF),"",DATA_REF-$G6) | J6: =IF($I6="","",MAX(0,$I6-5)) | K6: =IF($Z6="","PENDENTE",IF($I6="","",IFERROR(INDEX(CURVAS_KC!$B$5:$J$224,MATCH(MIN(MAX($J6,1),220),CURVAS_KC!$A$5:$A$224,0),MATCH($Z6,CURVAS_KC!$B$4:$J$4,0)),"PENDENTE"))) | L6: =IF($G6="","",$G6) | M6: =IF($L6="","",SUMIFS(ETO_SEMANAL!$B$6:$B$65,ETO_SEMANAL!$A$6:$A$65,">"&$L6,ETO_SEMANAL!$A$6:$A$65,"<="&DATA_REF)) | N6: =IF($L6="","",SUMIFS(ETO_SEMANAL!$C$6:$C$65,ETO_SEMANAL!$A$6:$A$65,">"&$L6,ETO_SEMANAL!$A$6:$A$65,"<="&DATA_REF)) | O6: =IF(OR($K6="",$K6="PENDENTE",$M6=""),"",$K6*$M6) | P6: =IF($O6="","",MAX(0,$O6-N($N6))) | Q6: =IF($P6="","",$P6/EF_APLIC) | S6: =IF(OR($AA6="",$R6=""),"",IFERROR(INDEX(LAMINA_HORA!$C$5:$V$114,MATCH($AA6,LAMINA_HORA!$A$5:$A$114,0),MATCH($R6,LAMINA_HORA!$C$3:$V$3,0)),"?")) | T6: =IF(OR($AA6="",$R6=""),"",IFERROR(INDEX(LAMINA_HORA!$W$5:$AP$114,MATCH($AA6,LAMINA_HORA!$A$5:$A$114,0),MATCH($R6,LAMINA_HORA!$W$3:$AP$3,0)),"?")) | U6: 0.513 | V6: =IF(OR($S6="",$S6="?",$F6=""),"",$S6*$F6*10) | W6: =IF(OR($V6="",$U6=""),"",$V6*$U6) | X6: =IF($K6="PENDENTE","Definir Kc",IF($P6="","-",IF($P6>=TURNO,"IRRIGAR",IF($P6>=TURNO*FRAC_ACOMP,"Acompanhar","Aguardar")))) | Y6: =IF(OR($P6="",$P6=0),"-",IF($P6>=2*TURNO,"Alta",IF($P6>=TURNO,"Media","Baixa"))) | Z6: SOJA_MEDIA | AA6: P1
A7: Pivô 02 | B7: Modulo 1 | C7: R0 | D7: CZ 37B07 I2X | E7: PRECOCE | F7: 124 | G7: 46287 | H7: =IF(OR($G7="",$G7>DATA_REF),"NAO","SIM") | I7: =IF(OR($G7="",$G7>DATA_REF),"",DATA_REF-$G7) | J7: =IF($I7="","",MAX(0,$I7-5)) | K7: =IF($Z7="","PENDENTE",IF($I7="","",IFERROR(INDEX(CURVAS_KC!$B$5:$J$224,MATCH(MIN(MAX($J7,1),220),CURVAS_KC!$A$5:$A$224,0),MATCH($Z7,CURVAS_KC!$B$4:$J$4,0)),"PENDENTE"))) | L7: =IF($G7="","",$G7) | M7: =IF($L7="","",SUMIFS(ETO_SEMANAL!$B$6:$B$65,ETO_SEMANAL!$A$6:$A$65,">"&$L7,ETO_SEMANAL!$A$6:$A$65,"<="&DATA_REF)) | N7: =IF($L7="","",SUMIFS(ETO_SEMANAL!$C$6:$C$65,ETO_SEMANAL!$A$6:$A$65,">"&$L7,ETO_SEMANAL!$A$6:$A$65,"<="&DATA_REF)) | O7: =IF(OR($K7="",$K7="PENDENTE",$M7=""),"",$K7*$M7) | P7: =IF($O7="","",MAX(0,$O7-N($N7))) | Q7: =IF($P7="","",$P7/EF_APLIC) | S7: =IF(OR($AA7="",$R7=""),"",IFERROR(INDEX(LAMINA_HORA!$C$5:$V$114,MATCH($AA7,LAMINA_HORA!$A$5:$A$114,0),MATCH($R7,LAMINA_HORA!$C$3:$V$3,0)),"?")) | T7: =IF(OR($AA7="",$R7=""),"",IFERROR(INDEX(LAMINA_HORA!$W$5:$AP$114,MATCH($AA7,LAMINA_HORA!$A$5:$A$114,0),MATCH($R7,LAMINA_HORA!$W$3:$AP$3,0)),"?")) | U7: 0.589 | V7: =IF(OR($S7="",$S7="?",$F7=""),"",$S7*$F7*10) | W7: =IF(OR($V7="",$U7=""),"",$V7*$U7) | X7: =IF($K7="PENDENTE","Definir Kc",IF($P7="","-",IF($P7>=TURNO,"IRRIGAR",IF($P7>=TURNO*FRAC_ACOMP,"Acompanhar","Aguardar")))) | Y7: =IF(OR($P7="",$P7=0),"-",IF($P7>=2*TURNO,"Alta",IF($P7>=TURNO,"Media","Baixa"))) | Z7: SOJA_PRECOCE | AA7: P2
A8: Pivô 02 | B8: Modulo 1 | C8: R0 | D8: BMX DOMINIO IPRO | E8: MEDIA | F8: 134 | G8: 46327 | H8: =IF(OR($G8="",$G8>DATA_REF),"NAO","SIM") | I8: =IF(OR($G8="",$G8>DATA_REF),"",DATA_REF-$G8) | J8: =IF($I8="","",MAX(0,$I8-5)) | K8: =IF($Z8="","PENDENTE",IF($I8="","",IFERROR(INDEX(CURVAS_KC!$B$5:$J$224,MATCH(MIN(MAX($J8,1),220),CURVAS_KC!$A$5:$A$224,0),MATCH($Z8,CURVAS_KC!$B$4:$J$4,0)),"PENDENTE"))) | L8: =IF($G8="","",$G8) | M8: =IF($L8="","",SUMIFS(ETO_SEMANAL!$B$6:$B$65,ETO_SEMANAL!$A$6:$A$65,">"&$L8,ETO_SEMANAL!$A$6:$A$65,"<="&DATA_REF)) | N8: =IF($L8="","",SUMIFS(ETO_SEMANAL!$C$6:$C$65,ETO_SEMANAL!$A$6:$A$65,">"&$L8,ETO_SEMANAL!$A$6:$A$65,"<="&DATA_REF)) | O8: =IF(OR($K8="",$K8="PENDENTE",$M8=""),"",$K8*$M8) | P8: =IF($O8="","",MAX(0,$O8-N($N8))) | Q8: =IF($P8="","",$P8/EF_APLIC) | S8: =IF(OR($AA8="",$R8=""),"",IFERROR(INDEX(LAMINA_HORA!$C$5:$V$114,MATCH($AA8,LAMINA_HORA!$A$5:$A$114,0),MATCH($R8,LAMINA_HORA!$C$3:$V$3,0)),"?")) | T8: =IF(OR($AA8="",$R8=""),"",IFERROR(INDEX(LAMINA_HORA!$W$5:$AP$114,MATCH($AA8,LAMINA_HORA!$A$5:$A$114,0),MATCH($R8,LAMINA_HORA!$W$3:$AP$3,0)),"?")) | U8: 0.589 | V8: =IF(OR($S8="",$S8="?",$F8=""),"",$S8*$F8*10) | W8: =IF(OR($V8="",$U8=""),"",$V8*$U8) | X8: =IF($K8="PENDENTE","Definir Kc",IF($P8="","-",IF($P8>=TURNO,"IRRIGAR",IF($P8>=TURNO*FRAC_ACOMP,"Acompanhar","Aguardar")))) | Y8: =IF(OR($P8="",$P8=0),"-",IF($P8>=2*TURNO,"Alta",IF($P8>=TURNO,"Media","Baixa"))) | Z8: SOJA_MEDIA | AA8: P2
A9: Pivô 02 | B9: Modulo 1 | C9: R0 | D9: BMX DOMINIO IPRO | E9: MEDIA | F9: 38 | G9: 46331 | H9: =IF(OR($G9="",$G9>DATA_REF),"NAO","SIM") | I9: =IF(OR($G9="",$G9>DATA_REF),"",DATA_REF-$G9) | J9: =IF($I9="","",MAX(0,$I9-5)) | K9: =IF($Z9="","PENDENTE",IF($I9="","",IFERROR(INDEX(CURVAS_KC!$B$5:$J$224,MATCH(MIN(MAX($J9,1),220),CURVAS_KC!$A$5:$A$224,0),MATCH($Z9,CURVAS_KC!$B$4:$J$4,0)),"PENDENTE"))) | L9: =IF($G9="","",$G9) | M9: =IF($L9="","",SUMIFS(ETO_SEMANAL!$B$6:$B$65,ETO_SEMANAL!$A$6:$A$65,">"&$L9,ETO_SEMANAL!$A$6:$A$65,"<="&DATA_REF)) | N9: =IF($L9="","",SUMIFS(ETO_SEMANAL!$C$6:$C$65,ETO_SEMANAL!$A$6:$A$65,">"&$L9,ETO_SEMANAL!$A$6:$A$65,"<="&DATA_REF)) | O9: =IF(OR($K9="",$K9="PENDENTE",$M9=""),"",$K9*$M9) | P9: =IF($O9="","",MAX(0,$O9-N($N9))) | Q9: =IF($P9="","",$P9/EF_APLIC) | S9: =IF(OR($AA9="",$R9=""),"",IFERROR(INDEX(LAMINA_HORA!$C$5:$V$114,MATCH($AA9,LAMINA_HORA!$A$5:$A$114,0),MATCH($R9,LAMINA_HORA!$C$3:$V$3,0)),"?")) | T9: =IF(OR($AA9="",$R9=""),"",IFERROR(INDEX(LAMINA_HORA!$W$5:$AP$114,MATCH($AA9,LAMINA_HORA!$A$5:$A$114,0),MATCH($R9,LAMINA_HORA!$W$3:$AP$3,0)),"?")) | U9: 0.589 | V9: =IF(OR($S9="",$S9="?",$F9=""),"",$S9*$F9*10) | W9: =IF(OR($V9="",$U9=""),"",$V9*$U9) | X9: =IF($K9="PENDENTE","Definir Kc",IF($P9="","-",IF($P9>=TURNO,"IRRIGAR",IF($P9>=TURNO*FRAC_ACOMP,"Acompanhar","Aguardar")))) | Y9: =IF(OR($P9="",$P9=0),"-",IF($P9>=2*TURNO,"Alta",IF($P9>=TURNO,"Media","Baixa"))) | Z9: SOJA_MEDIA | AA9: P2
A10: Pivô 03 | B10: Modulo 1 | C10: R0 | D10: COMBATE IPRO | E10: PRECOCE | F10: 150 | G10: 46288 | H10: =IF(OR($G10="",$G10>DATA_REF),"NAO","SIM") | I10: =IF(OR($G10="",$G10>DATA_REF),"",DATA_REF-$G10) | J10: =IF($I10="","",MAX(0,$I10-5)) | K10: =IF($Z10="","PENDENTE",IF($I10="","",IFERROR(INDEX(CURVAS_KC!$B$5:$J$224,MATCH(MIN(MAX($J10,1),220),CURVAS_KC!$A$5:$A$224,0),MATCH($Z10,CURVAS_KC!$B$4:$J$4,0)),"PENDENTE"))) | L10: =IF($G10="","",$G10) | M10: =IF($L10="","",SUMIFS(ETO_SEMANAL!$B$6:$B$65,ETO_SEMANAL!$A$6:$A$65,">"&$L10,ETO_SEMANAL!$A$6:$A$65,"<="&DATA_REF)) | N10: =IF($L10="","",SUMIFS(ETO_SEMANAL!$C$6:$C$65,ETO_SEMANAL!$A$6:$A$65,">"&$L10,ETO_SEMANAL!$A$6:$A$65,"<="&DATA_REF)) | O10: =IF(OR($K10="",$K10="PENDENTE",$M10=""),"",$K10*$M10) | P10: =IF($O10="","",MAX(0,$O10-N($N10))) | Q10: =IF($P10="","",$P10/EF_APLIC) | S10: =IF(OR($AA10="",$R10=""),"",IFERROR(INDEX(LAMINA_HORA!$C$5:$V$114,MATCH($AA10,LAMINA_HORA!$A$5:$A$114,0),MATCH($R10,LAMINA_HORA!$C$3:$V$3,0)),"?")) | T10: =IF(OR($AA10="",$R10=""),"",IFERROR(INDEX(LAMINA_HORA!$W$5:$AP$114,MATCH($AA10,LAMINA_HORA!$A$5:$A$114,0),MATCH($R10,LAMINA_HORA!$W$3:$AP$3,0)),"?")) | U10: 0.513 | V10: =IF(OR($S10="",$S10="?",$F10=""),"",$S10*$F10*10) | W10: =IF(OR($V10="",$U10=""),"",$V10*$U10) | X10: =IF($K10="PENDENTE","Definir Kc",IF($P10="","-",IF($P10>=TURNO,"IRRIGAR",IF($P10>=TURNO*FRAC_ACOMP,"Acompanhar","Aguardar")))) | Y10: =IF(OR($P10="",$P10=0),"-",IF($P10>=2*TURNO,"Alta",IF($P10>=TURNO,"Media","Baixa"))) | Z10: SOJA_PRECOCE | AA10: P3
A11: Pivô 03 | B11: Modulo 1 | C11: R0 | D11: MURALHA IPRO | E11: MEDIA | F11: 77 | G11: 46328 | H11: =IF(OR($G11="",$G11>DATA_REF),"NAO","SIM") | I11: =IF(OR($G11="",$G11>DATA_REF),"",DATA_REF-$G11) | J11: =IF($I11="","",MAX(0,$I11-5)) | K11: =IF($Z11="","PENDENTE",IF($I11="","",IFERROR(INDEX(CURVAS_KC!$B$5:$J$224,MATCH(MIN(MAX($J11,1),220),CURVAS_KC!$A$5:$A$224,0),MATCH($Z11,CURVAS_KC!$B$4:$J$4,0)),"PENDENTE"))) | L11: =IF($G11="","",$G11) | M11: =IF($L11="","",SUMIFS(ETO_SEMANAL!$B$6:$B$65,ETO_SEMANAL!$A$6:$A$65,">"&$L11,ETO_SEMANAL!$A$6:$A$65,"<="&DATA_REF)) | N11: =IF($L11="","",SUMIFS(ETO_SEMANAL!$C$6:$C$65,ETO_SEMANAL!$A$6:$A$65,">"&$L11,ETO_SEMANAL!$A$6:$A$65,"<="&DATA_REF)) | O11: =IF(OR($K11="",$K11="PENDENTE",$M11=""),"",$K11*$M11) | P11: =IF($O11="","",MAX(0,$O11-N($N11))) | Q11: =IF($P11="","",$P11/EF_APLIC) | S11: =IF(OR($AA11="",$R11=""),"",IFERROR(INDEX(LAMINA_HORA!$C$5:$V$114,MATCH($AA11,LAMINA_HORA!$A$5:$A$114,0),MATCH($R11,LAMINA_HORA!$C$3:$V$3,0)),"?")) | T11: =IF(OR($AA11="",$R11=""),"",IFERROR(INDEX(LAMINA_HORA!$W$5:$AP$114,MATCH($AA11,LAMINA_HORA!$A$5:$A$114,0),MATCH($R11,LAMINA_HORA!$W$3:$AP$3,0)),"?")) | U11: 0.513 | V11: =IF(OR($S11="",$S11="?",$F11=""),"",$S11*$F11*10) | W11: =IF(OR($V11="",$U11=""),"",$V11*$U11) | X11: =IF($K11="PENDENTE","Definir Kc",IF($P11="","-",IF($P11>=TURNO,"IRRIGAR",IF($P11>=TURNO*FRAC_ACOMP,"Acompanhar","Aguardar")))) | Y11: =IF(OR($P11="",$P11=0),"-",IF($P11>=2*TURNO,"Alta",IF($P11>=TURNO,"Media","Baixa"))) | Z11: SOJA_MEDIA | AA11: P3
A12: Pivô 03 | B12: Modulo 1 | C12: R0 | D12: BMX DOMINIO IPRO | E12: MEDIA | F12: 162 | G12: 46332 | H12: =IF(OR($G12="",$G12>DATA_REF),"NAO","SIM") | I12: =IF(OR($G12="",$G12>DATA_REF),"",DATA_REF-$G12) | J12: =IF($I12="","",MAX(0,$I12-5)) | K12: =IF($Z12="","PENDENTE",IF($I12="","",IFERROR(INDEX(CURVAS_KC!$B$5:$J$224,MATCH(MIN(MAX($J12,1),220),CURVAS_KC!$A$5:$A$224,0),MATCH($Z12,CURVAS_KC!$B$4:$J$4,0)),"PENDENTE"))) | L12: =IF($G12="","",$G12) | M12: =IF($L12="","",SUMIFS(ETO_SEMANAL!$B$6:$B$65,ETO_SEMANAL!$A$6:$A$65,">"&$L12,ETO_SEMANAL!$A$6:$A$65,"<="&DATA_REF)) | N12: =IF($L12="","",SUMIFS(ETO_SEMANAL!$C$6:$C$65,ETO_SEMANAL!$A$6:$A$65,">"&$L12,ETO_SEMANAL!$A$6:$A$65,"<="&DATA_REF)) | O12: =IF(OR($K12="",$K12="PENDENTE",$M12=""),"",$K12*$M12) | P12: =IF($O12="","",MAX(0,$O12-N($N12))) | Q12: =IF($P12="","",$P12/EF_APLIC) | S12: =IF(OR($AA12="",$R12=""),"",IFERROR(INDEX(LAMINA_HORA!$C$5:$V$114,MATCH($AA12,LAMINA_HORA!$A$5:$A$114,0),MATCH($R12,LAMINA_HORA!$C$3:$V$3,0)),"?")) | T12: =IF(OR($AA12="",$R12=""),"",IFERROR(INDEX(LAMINA_HORA!$W$5:$AP$114,MATCH($AA12,LAMINA_HORA!$A$5:$A$114,0),MATCH($R12,LAMINA_HORA!$W$3:$AP$3,0)),"?")) | U12: 0.513 | V12: =IF(OR($S12="",$S12="?",$F12=""),"",$S12*$F12*10) | W12: =IF(OR($V12="",$U12=""),"",$V12*$U12) | X12: =IF($K12="PENDENTE","Definir Kc",IF($P12="","-",IF($P12>=TURNO,"IRRIGAR",IF($P12>=TURNO*FRAC_ACOMP,"Acompanhar","Aguardar")))) | Y12: =IF(OR($P12="",$P12=0),"-",IF($P12>=2*TURNO,"Alta",IF($P12>=TURNO,"Media","Baixa"))) | Z12: SOJA_MEDIA | AA12: P3
A13: Pivô 04 | B13: Modulo 1 | C13: R0 | D13: COMBATE IPRO | E13: PRECOCE | F13: 63 | G13: 46288 | H13: =IF(OR($G13="",$G13>DATA_REF),"NAO","SIM") | I13: =IF(OR($G13="",$G13>DATA_REF),"",DATA_REF-$G13) | J13: =IF($I13="","",MAX(0,$I13-5)) | K13: =IF($Z13="","PENDENTE",IF($I13="","",IFERROR(INDEX(CURVAS_KC!$B$5:$J$224,MATCH(MIN(MAX($J13,1),220),CURVAS_KC!$A$5:$A$224,0),MATCH($Z13,CURVAS_KC!$B$4:$J$4,0)),"PENDENTE"))) | L13: =IF($G13="","",$G13) | M13: =IF($L13="","",SUMIFS(ETO_SEMANAL!$B$6:$B$65,ETO_SEMANAL!$A$6:$A$65,">"&$L13,ETO_SEMANAL!$A$6:$A$65,"<="&DATA_REF)) | N13: =IF($L13="","",SUMIFS(ETO_SEMANAL!$C$6:$C$65,ETO_SEMANAL!$A$6:$A$65,">"&$L13,ETO_SEMANAL!$A$6:$A$65,"<="&DATA_REF)) | O13: =IF(OR($K13="",$K13="PENDENTE",$M13=""),"",$K13*$M13) | P13: =IF($O13="","",MAX(0,$O13-N($N13))) | Q13: =IF($P13="","",$P13/EF_APLIC) | S13: =IF(OR($AA13="",$R13=""),"",IFERROR(INDEX(LAMINA_HORA!$C$5:$V$114,MATCH($AA13,LAMINA_HORA!$A$5:$A$114,0),MATCH($R13,LAMINA_HORA!$C$3:$V$3,0)),"?")) | T13: =IF(OR($AA13="",$R13=""),"",IFERROR(INDEX(LAMINA_HORA!$W$5:$AP$114,MATCH($AA13,LAMINA_HORA!$A$5:$A$114,0),MATCH($R13,LAMINA_HORA!$W$3:$AP$3,0)),"?")) | U13: 0.407 | V13: =IF(OR($S13="",$S13="?",$F13=""),"",$S13*$F13*10) | W13: =IF(OR($V13="",$U13=""),"",$V13*$U13) | X13: =IF($K13="PENDENTE","Definir Kc",IF($P13="","-",IF($P13>=TURNO,"IRRIGAR",IF($P13>=TURNO*FRAC_ACOMP,"Acompanhar","Aguardar")))) | Y13: =IF(OR($P13="",$P13=0),"-",IF($P13>=2*TURNO,"Alta",IF($P13>=TURNO,"Media","Baixa"))) | Z13: SOJA_PRECOCE | AA13: P4
A14: Pivô 04 | B14: Modulo 1 | C14: R0 | D14: BMX DOMINIO IPRO | E14: MEDIA | F14: 240 | G14: 46332 | H14: =IF(OR($G14="",$G14>DATA_REF),"NAO","SIM") | I14: =IF(OR($G14="",$G14>DATA_REF),"",DATA_REF-$G14) | J14: =IF($I14="","",MAX(0,$I14-5)) | K14: =IF($Z14="","PENDENTE",IF($I14="","",IFERROR(INDEX(CURVAS_KC!$B$5:$J$224,MATCH(MIN(MAX($J14,1),220),CURVAS_KC!$A$5:$A$224,0),MATCH($Z14,CURVAS_KC!$B$4:$J$4,0)),"PENDENTE"))) | L14: =IF($G14="","",$G14) | M14: =IF($L14="","",SUMIFS(ETO_SEMANAL!$B$6:$B$65,ETO_SEMANAL!$A$6:$A$65,">"&$L14,ETO_SEMANAL!$A$6:$A$65,"<="&DATA_REF)) | N14: =IF($L14="","",SUMIFS(ETO_SEMANAL!$C$6:$C$65,ETO_SEMANAL!$A$6:$A$65,">"&$L14,ETO_SEMANAL!$A$6:$A$65,"<="&DATA_REF)) | O14: =IF(OR($K14="",$K14="PENDENTE",$M14=""),"",$K14*$M14) | P14: =IF($O14="","",MAX(0,$O14-N($N14))) | Q14: =IF($P14="","",$P14/EF_APLIC) | S14: =IF(OR($AA14="",$R14=""),"",IFERROR(INDEX(LAMINA_HORA!$C$5:$V$114,MATCH($AA14,LAMINA_HORA!$A$5:$A$114,0),MATCH($R14,LAMINA_HORA!$C$3:$V$3,0)),"?")) | T14: =IF(OR($AA14="",$R14=""),"",IFERROR(INDEX(LAMINA_HORA!$W$5:$AP$114,MATCH($AA14,LAMINA_HORA!$A$5:$A$114,0),MATCH($R14,LAMINA_HORA!$W$3:$AP$3,0)),"?")) | U14: 0.407 | V14: =IF(OR($S14="",$S14="?",$F14=""),"",$S14*$F14*10) | W14: =IF(OR($V14="",$U14=""),"",$V14*$U14) | X14: =IF($K14="PENDENTE","Definir Kc",IF($P14="","-",IF($P14>=TURNO,"IRRIGAR",IF($P14>=TURNO*FRAC_ACOMP,"Acompanhar","Aguardar")))) | Y14: =IF(OR($P14="",$P14=0),"-",IF($P14>=2*TURNO,"Alta",IF($P14>=TURNO,"Media","Baixa"))) | Z14: SOJA_MEDIA | AA14: P4
A15: Pivô 05 | B15: Modulo 1 | C15: R1 | D15: COMBATE IPRO | E15: PRECOCE | F15: 150 | G15: 46289 | H15: =IF(OR($G15="",$G15>DATA_REF),"NAO","SIM") | I15: =IF(OR($G15="",$G15>DATA_REF),"",DATA_REF-$G15) | J15: =IF($I15="","",MAX(0,$I15-5)) | K15: =IF($Z15="","PENDENTE",IF($I15="","",IFERROR(INDEX(CURVAS_KC!$B$5:$J$224,MATCH(MIN(MAX($J15,1),220),CURVAS_KC!$A$5:$A$224,0),MATCH($Z15,CURVAS_KC!$B$4:$J$4,0)),"PENDENTE"))) | L15: =IF($G15="","",$G15) | M15: =IF($L15="","",SUMIFS(ETO_SEMANAL!$B$6:$B$65,ETO_SEMANAL!$A$6:$A$65,">"&$L15,ETO_SEMANAL!$A$6:$A$65,"<="&DATA_REF)) | N15: =IF($L15="","",SUMIFS(ETO_SEMANAL!$C$6:$C$65,ETO_SEMANAL!$A$6:$A$65,">"&$L15,ETO_SEMANAL!$A$6:$A$65,"<="&DATA_REF)) | O15: =IF(OR($K15="",$K15="PENDENTE",$M15=""),"",$K15*$M15) | P15: =IF($O15="","",MAX(0,$O15-N($N15))) | Q15: =IF($P15="","",$P15/EF_APLIC) | S15: =IF(OR($AA15="",$R15=""),"",IFERROR(INDEX(LAMINA_HORA!$C$5:$V$114,MATCH($AA15,LAMINA_HORA!$A$5:$A$114,0),MATCH($R15,LAMINA_HORA!$C$3:$V$3,0)),"?")) | T15: =IF(OR($AA15="",$R15=""),"",IFERROR(INDEX(LAMINA_HORA!$W$5:$AP$114,MATCH($AA15,LAMINA_HORA!$A$5:$A$114,0),MATCH($R15,LAMINA_HORA!$W$3:$AP$3,0)),"?")) | U15: 0.574 | V15: =IF(OR($S15="",$S15="?",$F15=""),"",$S15*$F15*10) | W15: =IF(OR($V15="",$U15=""),"",$V15*$U15) | X15: =IF($K15="PENDENTE","Definir Kc",IF($P15="","-",IF($P15>=TURNO,"IRRIGAR",IF($P15>=TURNO*FRAC_ACOMP,"Acompanhar","Aguardar")))) | Y15: =IF(OR($P15="",$P15=0),"-",IF($P15>=2*TURNO,"Alta",IF($P15>=TURNO,"Media","Baixa"))) | Z15: SOJA_PRECOCE | AA15: P5
A16: Pivô 05 | B16: Modulo 1 | C16: R1 | D16: BMX DOMINIO IPRO | E16: MEDIA | F16: 37 | G16: 46332 | H16: =IF(OR($G16="",$G16>DATA_REF),"NAO","SIM") | I16: =IF(OR($G16="",$G16>DATA_REF),"",DATA_REF-$G16) | J16: =IF($I16="","",MAX(0,$I16-5)) | K16: =IF($Z16="","PENDENTE",IF($I16="","",IFERROR(INDEX(CURVAS_KC!$B$5:$J$224,MATCH(MIN(MAX($J16,1),220),CURVAS_KC!$A$5:$A$224,0),MATCH($Z16,CURVAS_KC!$B$4:$J$4,0)),"PENDENTE"))) | L16: =IF($G16="","",$G16) | M16: =IF($L16="","",SUMIFS(ETO_SEMANAL!$B$6:$B$65,ETO_SEMANAL!$A$6:$A$65,">"&$L16,ETO_SEMANAL!$A$6:$A$65,"<="&DATA_REF)) | N16: =IF($L16="","",SUMIFS(ETO_SEMANAL!$C$6:$C$65,ETO_SEMANAL!$A$6:$A$65,">"&$L16,ETO_SEMANAL!$A$6:$A$65,"<="&DATA_REF)) | O16: =IF(OR($K16="",$K16="PENDENTE",$M16=""),"",$K16*$M16) | P16: =IF($O16="","",MAX(0,$O16-N($N16))) | Q16: =IF($P16="","",$P16/EF_APLIC) | S16: =IF(OR($AA16="",$R16=""),"",IFERROR(INDEX(LAMINA_HORA!$C$5:$V$114,MATCH($AA16,LAMINA_HORA!$A$5:$A$114,0),MATCH($R16,LAMINA_HORA!$C$3:$V$3,0)),"?")) | T16: =IF(OR($AA16="",$R16=""),"",IFERROR(INDEX(LAMINA_HORA!$W$5:$AP$114,MATCH($AA16,LAMINA_HORA!$A$5:$A$114,0),MATCH($R16,LAMINA_HORA!$W$3:$AP$3,0)),"?")) | U16: 0.574 | V16: =IF(OR($S16="",$S16="?",$F16=""),"",$S16*$F16*10) | W16: =IF(OR($V16="",$U16=""),"",$V16*$U16) | X16: =IF($K16="PENDENTE","Definir Kc",IF($P16="","-",IF($P16>=TURNO,"IRRIGAR",IF($P16>=TURNO*FRAC_ACOMP,"Acompanhar","Aguardar")))) | Y16: =IF(OR($P16="",$P16=0),"-",IF($P16>=2*TURNO,"Alta",IF($P16>=TURNO,"Media","Baixa"))) | Z16: SOJA_MEDIA | AA16: P5
... A88: Pivô 129 | B88: RDM | C88: RM6 | D88: NEO 761 I2X | E88: PRECOCE | F88: 100 | G88: 46308 | H88: =IF(OR($G88="",$G88>DATA_REF),"NAO","SIM") | I88: =IF(OR($G88="",$G88>DATA_REF),"",DATA_REF-$G88) | J88: =IF($I88="","",MAX(0,$I88-5)) | K88: =IF($Z88="","PENDENTE",IF($I88="","",IFERROR(INDEX(CURVAS_KC!$B$5:$J$224,MATCH(MIN(MAX($J88,1),220),CURVAS_KC!$A$5:$A$224,0),MATCH($Z88,CURVAS_KC!$B$4:$J$4,0)),"PENDENTE"))) | L88: =IF($G88="","",$G88) | M88: =IF($L88="","",SUMIFS(ETO_SEMANAL!$B$6:$B$65,ETO_SEMANAL!$A$6:$A$65,">"&$L88,ETO_SEMANAL!$A$6:$A$65,"<="&DATA_REF)) | N88: =IF($L88="","",SUMIFS(ETO_SEMANAL!$C$6:$C$65,ETO_SEMANAL!$A$6:$A$65,">"&$L88,ETO_SEMANAL!$A$6:$A$65,"<="&DATA_REF)) | O88: =IF(OR($K88="",$K88="PENDENTE",$M88=""),"",$K88*$M88) | P88: =IF($O88="","",MAX(0,$O88-N($N88))) | Q88: =IF($P88="","",$P88/EF_APLIC) | S88: =IF(OR($AA88="",$R88=""),"",IFERROR(INDEX(LAMINA_HORA!$C$5:$V$114,MATCH($AA88,LAMINA_HORA!$A$5:$A$114,0),MATCH($R88,LAMINA_HORA!$C$3:$V$3,0)),"?")) | T88: =IF(OR($AA88="",$R88=""),"",IFERROR(INDEX(LAMINA_HORA!$W$5:$AP$114,MATCH($AA88,LAMINA_HORA!$A$5:$A$114,0),MATCH($R88,LAMINA_HORA!$W$3:$AP$3,0)),"?")) | U88: 0.821 | V88: =IF(OR($S88="",$S88="?",$F88=""),"",$S88*$F88*10) | W88: =IF(OR($V88="",$U88=""),"",$V88*$U88) | X88: =IF($K88="PENDENTE","Definir Kc",IF($P88="","-",IF($P88>=TURNO,"IRRIGAR",IF($P88>=TURNO*FRAC_ACOMP,"Acompanhar","Aguardar")))) | Y88: =IF(OR($P88="",$P88=0),"-",IF($P88>=2*TURNO,"Alta",IF($P88>=TURNO,"Media","Baixa"))) | Z88: SOJA_PRECOCE | AA88: P129
A89: Nec BRUTA (azul) = lamina bruta ACUMULADA desde a ultima irrigacao (soma das ETos semanais x Kc, menos chuva, /0,90). Ao irrigar, atualize 'Ult.irrig'. So aparecem pivos plantados; preencha a Data plantio para um novo pivo e use Dados>Reaplicar.

Sheet ALGODAO
A1: ALGODAO 26/27 - manejo
A2: So pivos PLANTADOS (filtro Plantado=SIM). Avisar plantio = preencher Data plantio. Emergencia 5 dias. ETc=Kc(DAE)xETo semanal.
A4: Pivo | B4: Modulo | C4: Casa b. | D4: Variedade | E4: Classe | F4: Area(ha) | G4: Data plantio | H4: Plantado? | I4: DAP | J4: DAE | K4: Kc | L4: Ult.irrig | M4: ETo acum | N4: Chuva acum | O4: ETc acum | P4: Nec liq (mm) | Q4: Nec BRUTA (mm) | R4: % aplic | S4: Lamina(mm) | T4: Horas | U4: CE(kWh/m3) | V4: Volume(m3) | W4: Energia(kWh) | X4: Decisao | Y4: Prioridade | Z4: Curva Kc | AA4: Cod
A5: Nec BRUTA (azul) = lamina bruta ACUMULADA desde a ultima irrigacao (soma das ETos semanais x Kc, menos chuva, /0,90). Ao irrigar, atualize 'Ult.irrig'. So aparecem pivos plantados; preencha a Data plantio para um novo pivo e use Dados>Reaplicar.

Sheet TABACO
A1: TABACO 26/27 - manejo
A2: So pivos PLANTADOS (filtro Plantado=SIM). Avisar plantio = preencher Data plantio. Emergencia 0 dias. ETc=Kc(DAE)xETo semanal.
A4: Pivo | B4: Modulo | C4: Casa b. | D4: Variedade | E4: Classe | F4: Area(ha) | G4: Data plantio | H4: Plantado? | I4: DAP | J4: DAE | K4: Kc | L4: Ult.irrig | M4: ETo acum | N4: Chuva acum | O4: ETc acum | P4: Nec liq (mm) | Q4: Nec BRUTA (mm) | R4: % aplic | S4: Lamina(mm) | T4: Horas | U4: CE(kWh/m3) | V4: Volume(m3) | W4: Energia(kWh) | X4: Decisao | Y4: Prioridade | Z4: Curva Kc | AA4: Cod
A5: Pivô 118 | B5: RDM | C5: RM6 | D5: PVH-2343 | F5: 147 | G5: 46389 | H5: =IF(OR($G5="",$G5>DATA_REF),"NAO","SIM") | I5: =IF(OR($G5="",$G5>DATA_REF),"",DATA_REF-$G5) | J5: =IF($I5="","",MAX(0,$I5-0)) | K5: =IF($Z5="","PENDENTE",IF($I5="","",IFERROR(INDEX(CURVAS_KC!$B$5:$J$224,MATCH(MIN(MAX($J5,1),220),CURVAS_KC!$A$5:$A$224,0),MATCH($Z5,CURVAS_KC!$B$4:$J$4,0)),"PENDENTE"))) | L5: =IF($G5="","",$G5) | M5: =IF($L5="","",SUMIFS(ETO_SEMANAL!$B$6:$B$65,ETO_SEMANAL!$A$6:$A$65,">"&$L5,ETO_SEMANAL!$A$6:$A$65,"<="&DATA_REF)) | N5: =IF($L5="","",SUMIFS(ETO_SEMANAL!$C$6:$C$65,ETO_SEMANAL!$A$6:$A$65,">"&$L5,ETO_SEMANAL!$A$6:$A$65,"<="&DATA_REF)) | O5: =IF(OR($K5="",$K5="PENDENTE",$M5=""),"",$K5*$M5) | P5: =IF($O5="","",MAX(0,$O5-N($N5))) | Q5: =IF($P5="","",$P5/EF_APLIC) | S5: =IF(OR($AA5="",$R5=""),"",IFERROR(INDEX(LAMINA_HORA!$C$5:$V$114,MATCH($AA5,LAMINA_HORA!$A$5:$A$114,0),MATCH($R5,LAMINA_HORA!$C$3:$V$3,0)),"?")) | T5: =IF(OR($AA5="",$R5=""),"",IFERROR(INDEX(LAMINA_HORA!$W$5:$AP$114,MATCH($AA5,LAMINA_HORA!$A$5:$A$114,0),MATCH($R5,LAMINA_HORA!$W$3:$AP$3,0)),"?")) | U5: 0.703 | V5: =IF(OR($S5="",$S5="?",$F5=""),"",$S5*$F5*10) | W5: =IF(OR($V5="",$U5=""),"",$V5*$U5) | X5: =IF($K5="PENDENTE","Definir Kc",IF($P5="","-",IF($P5>=TURNO,"IRRIGAR",IF($P5>=TURNO*FRAC_ACOMP,"Acompanhar","Aguardar")))) | Y5: =IF(OR($P5="",$P5=0),"-",IF($P5>=2*TURNO,"Alta",IF($P5>=TURNO,"Media","Baixa"))) | Z5: TABACO | AA5: P118
A6: Pivô 119 | B6: RDM | C6: RM6 | D6: PVH-2343 | F6: 150 | G6: 46380 | H6: =IF(OR($G6="",$G6>DATA_REF),"NAO","SIM") | I6: =IF(OR($G6="",$G6>DATA_REF),"",DATA_REF-$G6) | J6: =IF($I6="","",MAX(0,$I6-0)) | K6: =IF($Z6="","PENDENTE",IF($I6="","",IFERROR(INDEX(CURVAS_KC!$B$5:$J$224,MATCH(MIN(MAX($J6,1),220),CURVAS_KC!$A$5:$A$224,0),MATCH($Z6,CURVAS_KC!$B$4:$J$4,0)),"PENDENTE"))) | L6: =IF($G6="","",$G6) | M6: =IF($L6="","",SUMIFS(ETO_SEMANAL!$B$6:$B$65,ETO_SEMANAL!$A$6:$A$65,">"&$L6,ETO_SEMANAL!$A$6:$A$65,"<="&DATA_REF)) | N6: =IF($L6="","",SUMIFS(ETO_SEMANAL!$C$6:$C$65,ETO_SEMANAL!$A$6:$A$65,">"&$L6,ETO_SEMANAL!$A$6:$A$65,"<="&DATA_REF)) | O6: =IF(OR($K6="",$K6="PENDENTE",$M6=""),"",$K6*$M6) | P6: =IF($O6="","",MAX(0,$O6-N($N6))) | Q6: =IF($P6="","",$P6/EF_APLIC) | S6: =IF(OR($AA6="",$R6=""),"",IFERROR(INDEX(LAMINA_HORA!$C$5:$V$114,MATCH($AA6,LAMINA_HORA!$A$5:$A$114,0),MATCH($R6,LAMINA_HORA!$C$3:$V$3,0)),"?")) | T6: =IF(OR($AA6="",$R6=""),"",IFERROR(INDEX(LAMINA_HORA!$W$5:$AP$114,MATCH($AA6,LAMINA_HORA!$A$5:$A$114,0),MATCH($R6,LAMINA_HORA!$W$3:$AP$3,0)),"?")) | U6: 0.724 | V6: =IF(OR($S6="",$S6="?",$F6=""),"",$S6*$F6*10) | W6: =IF(OR($V6="",$U6=""),"",$V6*$U6) | X6: =IF($K6="PENDENTE","Definir Kc",IF($P6="","-",IF($P6>=TURNO,"IRRIGAR",IF($P6>=TURNO*FRAC_ACOMP,"Acompanhar","Aguardar")))) | Y6: =IF(OR($P6="",$P6=0),"-",IF($P6>=2*TURNO,"Alta",IF($P6>=TURNO,"Media","Baixa"))) | Z6: TABACO | AA6: P119
A7: Pivô 120 | B7: RDM | C7: RM7 | D7: PVH-2343 | F7: 147 | G7: 46399 | H7: =IF(OR($G7="",$G7>DATA_REF),"NAO","SIM") | I7: =IF(OR($G7="",$G7>DATA_REF),"",DATA_REF-$G7) | J7: =IF($I7="","",MAX(0,$I7-0)) | K7: =IF($Z7="","PENDENTE",IF($I7="","",IFERROR(INDEX(CURVAS_KC!$B$5:$J$224,MATCH(MIN(MAX($J7,1),220),CURVAS_KC!$A$5:$A$224,0),MATCH($Z7,CURVAS_KC!$B$4:$J$4,0)),"PENDENTE"))) | L7: =IF($G7="","",$G7) | M7: =IF($L7="","",SUMIFS(ETO_SEMANAL!$B$6:$B$65,ETO_SEMANAL!$A$6:$A$65,">"&$L7,ETO_SEMANAL!$A$6:$A$65,"<="&DATA_REF)) | N7: =IF($L7="","",SUMIFS(ETO_SEMANAL!$C$6:$C$65,ETO_SEMANAL!$A$6:$A$65,">"&$L7,ETO_SEMANAL!$A$6:$A$65,"<="&DATA_REF)) | O7: =IF(OR($K7="",$K7="PENDENTE",$M7=""),"",$K7*$M7) | P7: =IF($O7="","",MAX(0,$O7-N($N7))) | Q7: =IF($P7="","",$P7/EF_APLIC) | S7: =IF(OR($AA7="",$R7=""),"",IFERROR(INDEX(LAMINA_HORA!$C$5:$V$114,MATCH($AA7,LAMINA_HORA!$A$5:$A$114,0),MATCH($R7,LAMINA_HORA!$C$3:$V$3,0)),"?")) | T7: =IF(OR($AA7="",$R7=""),"",IFERROR(INDEX(LAMINA_HORA!$W$5:$AP$114,MATCH($AA7,LAMINA_HORA!$A$5:$A$114,0),MATCH($R7,LAMINA_HORA!$W$3:$AP$3,0)),"?")) | U7: 0.724 | V7: =IF(OR($S7="",$S7="?",$F7=""),"",$S7*$F7*10) | W7: =IF(OR($V7="",$U7=""),"",$V7*$U7) | X7: =IF($K7="PENDENTE","Definir Kc",IF($P7="","-",IF($P7>=TURNO,"IRRIGAR",IF($P7>=TURNO*FRAC_ACOMP,"Acompanhar","Aguardar")))) | Y7: =IF(OR($P7="",$P7=0),"-",IF($P7>=2*TURNO,"Alta",IF($P7>=TURNO,"Media","Baixa"))) | Z7: TABACO | AA7: P120
A8: Pivô 126 | B8: RDM | C8: RM7 | D8: PVH-2343 | F8: 140 | G8: 46371 | H8: =IF(OR($G8="",$G8>DATA_REF),"NAO","SIM") | I8: =IF(OR($G8="",$G8>DATA_REF),"",DATA_REF-$G8) | J8: =IF($I8="","",MAX(0,$I8-0)) | K8: =IF($Z8="","PENDENTE",IF($I8="","",IFERROR(INDEX(CURVAS_KC!$B$5:$J$224,MATCH(MIN(MAX($J8,1),220),CURVAS_KC!$A$5:$A$224,0),MATCH($Z8,CURVAS_KC!$B$4:$J$4,0)),"PENDENTE"))) | L8: =IF($G8="","",$G8) | M8: =IF($L8="","",SUMIFS(ETO_SEMANAL!$B$6:$B$65,ETO_SEMANAL!$A$6:$A$65,">"&$L8,ETO_SEMANAL!$A$6:$A$65,"<="&DATA_REF)) | N8: =IF($L8="","",SUMIFS(ETO_SEMANAL!$C$6:$C$65,ETO_SEMANAL!$A$6:$A$65,">"&$L8,ETO_SEMANAL!$A$6:$A$65,"<="&DATA_REF)) | O8: =IF(OR($K8="",$K8="PENDENTE",$M8=""),"",$K8*$M8) | P8: =IF($O8="","",MAX(0,$O8-N($N8))) | Q8: =IF($P8="","",$P8/EF_APLIC) | S8: =IF(OR($AA8="",$R8=""),"",IFERROR(INDEX(LAMINA_HORA!$C$5:$V$114,MATCH($AA8,LAMINA_HORA!$A$5:$A$114,0),MATCH($R8,LAMINA_HORA!$C$3:$V$3,0)),"?")) | T8: =IF(OR($AA8="",$R8=""),"",IFERROR(INDEX(LAMINA_HORA!$W$5:$AP$114,MATCH($AA8,LAMINA_HORA!$A$5:$A$114,0),MATCH($R8,LAMINA_HORA!$W$3:$AP$3,0)),"?")) | U8: 0.711 | V8: =IF(OR($S8="",$S8="?",$F8=""),"",$S8*$F8*10) | W8: =IF(OR($V8="",$U8=""),"",$V8*$U8) | X8: =IF($K8="PENDENTE","Definir Kc",IF($P8="","-",IF($P8>=TURNO,"IRRIGAR",IF($P8>=TURNO*FRAC_ACOMP,"Acompanhar","Aguardar")))) | Y8: =IF(OR($P8="",$P8=0),"-",IF($P8>=2*TURNO,"Alta",IF($P8>=TURNO,"Media","Baixa"))) | Z8: TABACO | AA8: P126
A9: Pivô 128 | B9: RDM | C9: RM6 | D9: PVH-2343 | F9: 140 | G9: 46345 | H9: =IF(OR($G9="",$G9>DATA_REF),"NAO","SIM") | I9: =IF(OR($G9="",$G9>DATA_REF),"",DATA_REF-$G9) | J9: =IF($I9="","",MAX(0,$I9-0)) | K9: =IF($Z9="","PENDENTE",IF($I9="","",IFERROR(INDEX(CURVAS_KC!$B$5:$J$224,MATCH(MIN(MAX($J9,1),220),CURVAS_KC!$A$5:$A$224,0),MATCH($Z9,CURVAS_KC!$B$4:$J$4,0)),"PENDENTE"))) | L9: =IF($G9="","",$G9) | M9: =IF($L9="","",SUMIFS(ETO_SEMANAL!$B$6:$B$65,ETO_SEMANAL!$A$6:$A$65,">"&$L9,ETO_SEMANAL!$A$6:$A$65,"<="&DATA_REF)) | N9: =IF($L9="","",SUMIFS(ETO_SEMANAL!$C$6:$C$65,ETO_SEMANAL!$A$6:$A$65,">"&$L9,ETO_SEMANAL!$A$6:$A$65,"<="&DATA_REF)) | O9: =IF(OR($K9="",$K9="PENDENTE",$M9=""),"",$K9*$M9) | P9: =IF($O9="","",MAX(0,$O9-N($N9))) | Q9: =IF($P9="","",$P9/EF_APLIC) | S9: =IF(OR($AA9="",$R9=""),"",IFERROR(INDEX(LAMINA_HORA!$C$5:$V$114,MATCH($AA9,LAMINA_HORA!$A$5:$A$114,0),MATCH($R9,LAMINA_HORA!$C$3:$V$3,0)),"?")) | T9: =IF(OR($AA9="",$R9=""),"",IFERROR(INDEX(LAMINA_HORA!$W$5:$AP$114,MATCH($AA9,LAMINA_HORA!$A$5:$A$114,0),MATCH($R9,LAMINA_HORA!$W$3:$AP$3,0)),"?")) | U9: 0.711 | V9: =IF(OR($S9="",$S9="?",$F9=""),"",$S9*$F9*10) | W9: =IF(OR($V9="",$U9=""),"",$V9*$U9) | X9: =IF($K9="PENDENTE","Definir Kc",IF($P9="","-",IF($P9>=TURNO,"IRRIGAR",IF($P9>=TURNO*FRAC_ACOMP,"Acompanhar","Aguardar")))) | Y9: =IF(OR($P9="",$P9=0),"-",IF($P9>=2*TURNO,"Alta",IF($P9>=TURNO,"Media","Baixa"))) | Z9: TABACO | AA9: P128
A10: Nec BRUTA (azul) = lamina bruta ACUMULADA desde a ultima irrigacao (soma das ETos semanais x Kc, menos chuva, /0,90). Ao irrigar, atualize 'Ult.irrig'. So aparecem pivos plantados; preencha a Data plantio para um novo pivo e use Dados>Reaplicar.

Sheet CACAU
A1: CACAU - manejo (perene)
A2: So pivos PLANTADOS (filtro Plantado=SIM). Avisar plantio = preencher Data plantio. Emergencia 0 dias. ETc=Kc(DAE)xETo semanal.
A4: Pivo | B4: Modulo | C4: Casa b. | D4: Variedade | E4: Classe | F4: Area(ha) | G4: Data plantio | H4: Plantado? | I4: DAP | J4: DAE | K4: Kc | L4: Ult.irrig | M4: ETo acum | N4: Chuva acum | O4: ETc acum | P4: Nec liq (mm) | Q4: Nec BRUTA (mm) | R4: % aplic | S4: Lamina(mm) | T4: Horas | U4: CE(kWh/m3) | V4: Volume(m3) | W4: Energia(kWh) | X4: Decisao | Y4: Prioridade | Z4: Curva Kc | AA4: Cod
A5: Pivô 01 | B5: Modulo 1 | C5: R0 | D5: PS1319/FA13/CCN51 | F5: 47.5 | G5: 45901 | H5: =IF(OR($G5="",$G5>DATA_REF),"NAO","SIM") | I5: =IF(OR($G5="",$G5>DATA_REF),"",DATA_REF-$G5) | J5: =IF($I5="","",MAX(0,$I5-0)) | K5: =IF($Z5="","PENDENTE",IF($I5="","",IFERROR(INDEX(CURVAS_KC!$B$5:$J$224,MATCH(MIN(MAX($J5,1),220),CURVAS_KC!$A$5:$A$224,0),MATCH($Z5,CURVAS_KC!$B$4:$J$4,0)),"PENDENTE"))) | L5: =IF($G5="","",$G5) | M5: =IF($L5="","",SUMIFS(ETO_SEMANAL!$B$6:$B$65,ETO_SEMANAL!$A$6:$A$65,">"&$L5,ETO_SEMANAL!$A$6:$A$65,"<="&DATA_REF)) | N5: =IF($L5="","",SUMIFS(ETO_SEMANAL!$C$6:$C$65,ETO_SEMANAL!$A$6:$A$65,">"&$L5,ETO_SEMANAL!$A$6:$A$65,"<="&DATA_REF)) | O5: =IF(OR($K5="",$K5="PENDENTE",$M5=""),"",$K5*$M5) | P5: =IF($O5="","",MAX(0,$O5-N($N5))) | Q5: =IF($P5="","",$P5/EF_APLIC) | S5: =IF(OR($AA5="",$R5=""),"",IFERROR(INDEX(LAMINA_HORA!$C$5:$V$114,MATCH($AA5,LAMINA_HORA!$A$5:$A$114,0),MATCH($R5,LAMINA_HORA!$C$3:$V$3,0)),"?")) | T5: =IF(OR($AA5="",$R5=""),"",IFERROR(INDEX(LAMINA_HORA!$W$5:$AP$114,MATCH($AA5,LAMINA_HORA!$A$5:$A$114,0),MATCH($R5,LAMINA_HORA!$W$3:$AP$3,0)),"?")) | U5: 0.513 | V5: =IF(OR($S5="",$S5="?",$F5=""),"",$S5*$F5*10) | W5: =IF(OR($V5="",$U5=""),"",$V5*$U5) | X5: =IF($K5="PENDENTE","Definir Kc",IF($P5="","-",IF($P5>=TURNO,"IRRIGAR",IF($P5>=TURNO*FRAC_ACOMP,"Acompanhar","Aguardar")))) | Y5: =IF(OR($P5="",$P5=0),"-",IF($P5>=2*TURNO,"Alta",IF($P5>=TURNO,"Media","Baixa"))) | Z5: CACAU | AA5: P1
A6: Pivô 02 | B6: Modulo 1 | C6: R0 | D6: PS1319/FA13/CCN51 | F6: 131.5 | G6: 45901 | H6: =IF(OR($G6="",$G6>DATA_REF),"NAO","SIM") | I6: =IF(OR($G6="",$G6>DATA_REF),"",DATA_REF-$G6) | J6: =IF($I6="","",MAX(0,$I6-0)) | K6: =IF($Z6="","PENDENTE",IF($I6="","",IFERROR(INDEX(CURVAS_KC!$B$5:$J$224,MATCH(MIN(MAX($J6,1),220),CURVAS_KC!$A$5:$A$224,0),MATCH($Z6,CURVAS_KC!$B$4:$J$4,0)),"PENDENTE"))) | L6: =IF($G6="","",$G6) | M6: =IF($L6="","",SUMIFS(ETO_SEMANAL!$B$6:$B$65,ETO_SEMANAL!$A$6:$A$65,">"&$L6,ETO_SEMANAL!$A$6:$A$65,"<="&DATA_REF)) | N6: =IF($L6="","",SUMIFS(ETO_SEMANAL!$C$6:$C$65,ETO_SEMANAL!$A$6:$A$65,">"&$L6,ETO_SEMANAL!$A$6:$A$65,"<="&DATA_REF)) | O6: =IF(OR($K6="",$K6="PENDENTE",$M6=""),"",$K6*$M6) | P6: =IF($O6="","",MAX(0,$O6-N($N6))) | Q6: =IF($P6="","",$P6/EF_APLIC) | S6: =IF(OR($AA6="",$R6=""),"",IFERROR(INDEX(LAMINA_HORA!$C$5:$V$114,MATCH($AA6,LAMINA_HORA!$A$5:$A$114,0),MATCH($R6,LAMINA_HORA!$C$3:$V$3,0)),"?")) | T6: =IF(OR($AA6="",$R6=""),"",IFERROR(INDEX(LAMINA_HORA!$W$5:$AP$114,MATCH($AA6,LAMINA_HORA!$A$5:$A$114,0),MATCH($R6,LAMINA_HORA!$W$3:$AP$3,0)),"?")) | U6: 0.589 | V6: =IF(OR($S6="",$S6="?",$F6=""),"",$S6*$F6*10) | W6: =IF(OR($V6="",$U6=""),"",$V6*$U6) | X6: =IF($K6="PENDENTE","Definir Kc",IF($P6="","-",IF($P6>=TURNO,"IRRIGAR",IF($P6>=TURNO*FRAC_ACOMP,"Acompanhar","Aguardar")))) | Y6: =IF(OR($P6="",$P6=0),"-",IF($P6>=2*TURNO,"Alta",IF($P6>=TURNO,"Media","Baixa"))) | Z6: CACAU | AA6: P2
A7: Pivô 03 | B7: Modulo 1 | C7: R0 | D7: PS1319/FA13/CCN51 | F7: 82.8 | G7: 45901 | H7: =IF(OR($G7="",$G7>DATA_REF),"NAO","SIM") | I7: =IF(OR($G7="",$G7>DATA_REF),"",DATA_REF-$G7) | J7: =IF($I7="","",MAX(0,$I7-0)) | K7: =IF($Z7="","PENDENTE",IF($I7="","",IFERROR(INDEX(CURVAS_KC!$B$5:$J$224,MATCH(MIN(MAX($J7,1),220),CURVAS_KC!$A$5:$A$224,0),MATCH($Z7,CURVAS_KC!$B$4:$J$4,0)),"PENDENTE"))) | L7: =IF($G7="","",$G7) | M7: =IF($L7="","",SUMIFS(ETO_SEMANAL!$B$6:$B$65,ETO_SEMANAL!$A$6:$A$65,">"&$L7,ETO_SEMANAL!$A$6:$A$65,"<="&DATA_REF)) | N7: =IF($L7="","",SUMIFS(ETO_SEMANAL!$C$6:$C$65,ETO_SEMANAL!$A$6:$A$65,">"&$L7,ETO_SEMANAL!$A$6:$A$65,"<="&DATA_REF)) | O7: =IF(OR($K7="",$K7="PENDENTE",$M7=""),"",$K7*$M7) | P7: =IF($O7="","",MAX(0,$O7-N($N7))) | Q7: =IF($P7="","",$P7/EF_APLIC) | S7: =IF(OR($AA7="",$R7=""),"",IFERROR(INDEX(LAMINA_HORA!$C$5:$V$114,MATCH($AA7,LAMINA_HORA!$A$5:$A$114,0),MATCH($R7,LAMINA_HORA!$C$3:$V$3,0)),"?")) | T7: =IF(OR($AA7="",$R7=""),"",IFERROR(INDEX(LAMINA_HORA!$W$5:$AP$114,MATCH($AA7,LAMINA_HORA!$A$5:$A$114,0),MATCH($R7,LAMINA_HORA!$W$3:$AP$3,0)),"?")) | U7: 0.513 | V7: =IF(OR($S7="",$S7="?",$F7=""),"",$S7*$F7*10) | W7: =IF(OR($V7="",$U7=""),"",$V7*$U7) | X7: =IF($K7="PENDENTE","Definir Kc",IF($P7="","-",IF($P7>=TURNO,"IRRIGAR",IF($P7>=TURNO*FRAC_ACOMP,"Acompanhar","Aguardar")))) | Y7: =IF(OR($P7="",$P7=0),"-",IF($P7>=2*TURNO,"Alta",IF($P7>=TURNO,"Media","Baixa"))) | Z7: CACAU | AA7: P3
A8: Pivô 25 | B8: Modulo 1 | C8: R7 | D8: PS1319/FA13/CCN51 | F8: 100 | G8: 45901 | H8: =IF(OR($G8="",$G8>DATA_REF),"NAO","SIM") | I8: =IF(OR($G8="",$G8>DATA_REF),"",DATA_REF-$G8) | J8: =IF($I8="","",MAX(0,$I8-0)) | K8: =IF($Z8="","PENDENTE",IF($I8="","",IFERROR(INDEX(CURVAS_KC!$B$5:$J$224,MATCH(MIN(MAX($J8,1),220),CURVAS_KC!$A$5:$A$224,0),MATCH($Z8,CURVAS_KC!$B$4:$J$4,0)),"PENDENTE"))) | L8: =IF($G8="","",$G8) | M8: =IF($L8="","",SUMIFS(ETO_SEMANAL!$B$6:$B$65,ETO_SEMANAL!$A$6:$A$65,">"&$L8,ETO_SEMANAL!$A$6:$A$65,"<="&DATA_REF)) | N8: =IF($L8="","",SUMIFS(ETO_SEMANAL!$C$6:$C$65,ETO_SEMANAL!$A$6:$A$65,">"&$L8,ETO_SEMANAL!$A$6:$A$65,"<="&DATA_REF)) | O8: =IF(OR($K8="",$K8="PENDENTE",$M8=""),"",$K8*$M8) | P8: =IF($O8="","",MAX(0,$O8-N($N8))) | Q8: =IF($P8="","",$P8/EF_APLIC) | S8: =IF(OR($AA8="",$R8=""),"",IFERROR(INDEX(LAMINA_HORA!$C$5:$V$114,MATCH($AA8,LAMINA_HORA!$A$5:$A$114,0),MATCH($R8,LAMINA_HORA!$C$3:$V$3,0)),"?")) | T8: =IF(OR($AA8="",$R8=""),"",IFERROR(INDEX(LAMINA_HORA!$W$5:$AP$114,MATCH($AA8,LAMINA_HORA!$A$5:$A$114,0),MATCH($R8,LAMINA_HORA!$W$3:$AP$3,0)),"?")) | U8: 0.462 | V8: =IF(OR($S8="",$S8="?",$F8=""),"",$S8*$F8*10) | W8: =IF(OR($V8="",$U8=""),"",$V8*$U8) | X8: =IF($K8="PENDENTE","Definir Kc",IF($P8="","-",IF($P8>=TURNO,"IRRIGAR",IF($P8>=TURNO*FRAC_ACOMP,"Acompanhar","Aguardar")))) | Y8: =IF(OR($P8="",$P8=0),"-",IF($P8>=2*TURNO,"Alta",IF($P8>=TURNO,"Media","Baixa"))) | Z8: CACAU | AA8: P25
A9: Pivô 27 | B9: Modulo 1 | C9: R7 | D9: PS1319/FA13/CCN51 | F9: 100 | G9: 45901 | H9: =IF(OR($G9="",$G9>DATA_REF),"NAO","SIM") | I9: =IF(OR($G9="",$G9>DATA_REF),"",DATA_REF-$G9) | J9: =IF($I9="","",MAX(0,$I9-0)) | K9: =IF($Z9="","PENDENTE",IF($I9="","",IFERROR(INDEX(CURVAS_KC!$B$5:$J$224,MATCH(MIN(MAX($J9,1),220),CURVAS_KC!$A$5:$A$224,0),MATCH($Z9,CURVAS_KC!$B$4:$J$4,0)),"PENDENTE"))) | L9: =IF($G9="","",$G9) | M9: =IF($L9="","",SUMIFS(ETO_SEMANAL!$B$6:$B$65,ETO_SEMANAL!$A$6:$A$65,">"&$L9,ETO_SEMANAL!$A$6:$A$65,"<="&DATA_REF)) | N9: =IF($L9="","",SUMIFS(ETO_SEMANAL!$C$6:$C$65,ETO_SEMANAL!$A$6:$A$65,">"&$L9,ETO_SEMANAL!$A$6:$A$65,"<="&DATA_REF)) | O9: =IF(OR($K9="",$K9="PENDENTE",$M9=""),"",$K9*$M9) | P9: =IF($O9="","",MAX(0,$O9-N($N9))) | Q9: =IF($P9="","",$P9/EF_APLIC) | S9: =IF(OR($AA9="",$R9=""),"",IFERROR(INDEX(LAMINA_HORA!$C$5:$V$114,MATCH($AA9,LAMINA_HORA!$A$5:$A$114,0),MATCH($R9,LAMINA_HORA!$C$3:$V$3,0)),"?")) | T9: =IF(OR($AA9="",$R9=""),"",IFERROR(INDEX(LAMINA_HORA!$W$5:$AP$114,MATCH($AA9,LAMINA_HORA!$A$5:$A$114,0),MATCH($R9,LAMINA_HORA!$W$3:$AP$3,0)),"?")) | U9: 0.463 | V9: =IF(OR($S9="",$S9="?",$F9=""),"",$S9*$F9*10) | W9: =IF(OR($V9="",$U9=""),"",$V9*$U9) | X9: =IF($K9="PENDENTE","Definir Kc",IF($P9="","-",IF($P9>=TURNO,"IRRIGAR",IF($P9>=TURNO*FRAC_ACOMP,"Acompanhar","Aguardar")))) | Y9: =IF(OR($P9="",$P9=0),"-",IF($P9>=2*TURNO,"Alta",IF($P9>=TURNO,"Media","Baixa"))) | Z9: CACAU | AA9: P27
A10: Pivô 28 | B10: Modulo 1 | C10: R7 | D10: PS1319/FA13/CCN51 | F10: 133 | G10: 46196 | H10: =IF(OR($G10="",$G10>DATA_REF),"NAO","SIM") | I10: =IF(OR($G10="",$G10>DATA_REF),"",DATA_REF-$G10) | J10: =IF($I10="","",MAX(0,$I10-0)) | K10: =IF($Z10="","PENDENTE",IF($I10="","",IFERROR(INDEX(CURVAS_KC!$B$5:$J$224,MATCH(MIN(MAX($J10,1),220),CURVAS_KC!$A$5:$A$224,0),MATCH($Z10,CURVAS_KC!$B$4:$J$4,0)),"PENDENTE"))) | L10: =IF($G10="","",$G10) | M10: =IF($L10="","",SUMIFS(ETO_SEMANAL!$B$6:$B$65,ETO_SEMANAL!$A$6:$A$65,">"&$L10,ETO_SEMANAL!$A$6:$A$65,"<="&DATA_REF)) | N10: =IF($L10="","",SUMIFS(ETO_SEMANAL!$C$6:$C$65,ETO_SEMANAL!$A$6:$A$65,">"&$L10,ETO_SEMANAL!$A$6:$A$65,"<="&DATA_REF)) | O10: =IF(OR($K10="",$K10="PENDENTE",$M10=""),"",$K10*$M10) | P10: =IF($O10="","",MAX(0,$O10-N($N10))) | Q10: =IF($P10="","",$P10/EF_APLIC) | S10: =IF(OR($AA10="",$R10=""),"",IFERROR(INDEX(LAMINA_HORA!$C$5:$V$114,MATCH($AA10,LAMINA_HORA!$A$5:$A$114,0),MATCH($R10,LAMINA_HORA!$C$3:$V$3,0)),"?")) | T10: =IF(OR($AA10="",$R10=""),"",IFERROR(INDEX(LAMINA_HORA!$W$5:$AP$114,MATCH($AA10,LAMINA_HORA!$A$5:$A$114,0),MATCH($R10,LAMINA_HORA!$W$3:$AP$3,0)),"?")) | U10: 0.54 | V10: =IF(OR($S10="",$S10="?",$F10=""),"",$S10*$F10*10) | W10: =IF(OR($V10="",$U10=""),"",$V10*$U10) | X10: =IF($K10="PENDENTE","Definir Kc",IF($P10="","-",IF($P10>=TURNO,"IRRIGAR",IF($P10>=TURNO*FRAC_ACOMP,"Acompanhar","Aguardar")))) | Y10: =IF(OR($P10="",$P10=0),"-",IF($P10>=2*TURNO,"Alta",IF($P10>=TURNO,"Media","Baixa"))) | Z10: CACAU | AA10: P28
A11: Pivô 29 | B11: Modulo 1 | C11: R7 | D11: PS1319/FA13/CCN51 | F11: 80 | G11: 45901 | H11: =IF(OR($G11="",$G11>DATA_REF),"NAO","SIM") | I11: =IF(OR($G11="",$G11>DATA_REF),"",DATA_REF-$G11) | J11: =IF($I11="","",MAX(0,$I11-0)) | K11: =IF($Z11="","PENDENTE",IF($I11="","",IFERROR(INDEX(CURVAS_KC!$B$5:$J$224,MATCH(MIN(MAX($J11,1),220),CURVAS_KC!$A$5:$A$224,0),MATCH($Z11,CURVAS_KC!$B$4:$J$4,0)),"PENDENTE"))) | L11: =IF($G11="","",$G11) | M11: =IF($L11="","",SUMIFS(ETO_SEMANAL!$B$6:$B$65,ETO_SEMANAL!$A$6:$A$65,">"&$L11,ETO_SEMANAL!$A$6:$A$65,"<="&DATA_REF)) | N11: =IF($L11="","",SUMIFS(ETO_SEMANAL!$C$6:$C$65,ETO_SEMANAL!$A$6:$A$65,">"&$L11,ETO_SEMANAL!$A$6:$A$65,"<="&DATA_REF)) | O11: =IF(OR($K11="",$K11="PENDENTE",$M11=""),"",$K11*$M11) | P11: =IF($O11="","",MAX(0,$O11-N($N11))) | Q11: =IF($P11="","",$P11/EF_APLIC) | S11: =IF(OR($AA11="",$R11=""),"",IFERROR(INDEX(LAMINA_HORA!$C$5:$V$114,MATCH($AA11,LAMINA_HORA!$A$5:$A$114,0),MATCH($R11,LAMINA_HORA!$C$3:$V$3,0)),"?")) | T11: =IF(OR($AA11="",$R11=""),"",IFERROR(INDEX(LAMINA_HORA!$W$5:$AP$114,MATCH($AA11,LAMINA_HORA!$A$5:$A$114,0),MATCH($R11,LAMINA_HORA!$W$3:$AP$3,0)),"?")) | U11: 0.504 | V11: =IF(OR($S11="",$S11="?",$F11=""),"",$S11*$F11*10) | W11: =IF(OR($V11="",$U11=""),"",$V11*$U11) | X11: =IF($K11="PENDENTE","Definir Kc",IF($P11="","-",IF($P11>=TURNO,"IRRIGAR",IF($P11>=TURNO*FRAC_ACOMP,"Acompanhar","Aguardar")))) | Y11: =IF(OR($P11="",$P11=0),"-",IF($P11>=2*TURNO,"Alta",IF($P11>=TURNO,"Media","Baixa"))) | Z11: CACAU | AA11: P29
A12: Pivô 30 | B12: Modulo 1 | C12: C3Z3/R7 | D12: PS1319/FA13/CCN51 | F12: 150 | G12: 46447 | H12: =IF(OR($G12="",$G12>DATA_REF),"NAO","SIM") | I12: =IF(OR($G12="",$G12>DATA_REF),"",DATA_REF-$G12) | J12: =IF($I12="","",MAX(0,$I12-0)) | K12: =IF($Z12="","PENDENTE",IF($I12="","",IFERROR(INDEX(CURVAS_KC!$B$5:$J$224,MATCH(MIN(MAX($J12,1),220),CURVAS_KC!$A$5:$A$224,0),MATCH($Z12,CURVAS_KC!$B$4:$J$4,0)),"PENDENTE"))) | L12: =IF($G12="","",$G12) | M12: =IF($L12="","",SUMIFS(ETO_SEMANAL!$B$6:$B$65,ETO_SEMANAL!$A$6:$A$65,">"&$L12,ETO_SEMANAL!$A$6:$A$65,"<="&DATA_REF)) | N12: =IF($L12="","",SUMIFS(ETO_SEMANAL!$C$6:$C$65,ETO_SEMANAL!$A$6:$A$65,">"&$L12,ETO_SEMANAL!$A$6:$A$65,"<="&DATA_REF)) | O12: =IF(OR($K12="",$K12="PENDENTE",$M12=""),"",$K12*$M12) | P12: =IF($O12="","",MAX(0,$O12-N($N12))) | Q12: =IF($P12="","",$P12/EF_APLIC) | S12: =IF(OR($AA12="",$R12=""),"",IFERROR(INDEX(LAMINA_HORA!$C$5:$V$114,MATCH($AA12,LAMINA_HORA!$A$5:$A$114,0),MATCH($R12,LAMINA_HORA!$C$3:$V$3,0)),"?")) | T12: =IF(OR($AA12="",$R12=""),"",IFERROR(INDEX(LAMINA_HORA!$W$5:$AP$114,MATCH($AA12,LAMINA_HORA!$A$5:$A$114,0),MATCH($R12,LAMINA_HORA!$W$3:$AP$3,0)),"?")) | U12: 0.441 | V12: =IF(OR($S12="",$S12="?",$F12=""),"",$S12*$F12*10) | W12: =IF(OR($V12="",$U12=""),"",$V12*$U12) | X12: =IF($K12="PENDENTE","Definir Kc",IF($P12="","-",IF($P12>=TURNO,"IRRIGAR",IF($P12>=TURNO*FRAC_ACOMP,"Acompanhar","Aguardar")))) | Y12: =IF(OR($P12="",$P12=0),"-",IF($P12>=2*TURNO,"Alta",IF($P12>=TURNO,"Media","Baixa"))) | Z12: CACAU | AA12: P30
A13: Pivô 31 | B13: Modulo 1 | C13: C3Z3/R7 | D13: PS1319/FA13/CCN51 | F13: 150 | G13: 46357 | H13: =IF(OR($G13="",$G13>DATA_REF),"NAO","SIM") | I13: =IF(OR($G13="",$G13>DATA_REF),"",DATA_REF-$G13) | J13: =IF($I13="","",MAX(0,$I13-0)) | K13: =IF($Z13="","PENDENTE",IF($I13="","",IFERROR(INDEX(CURVAS_KC!$B$5:$J$224,MATCH(MIN(MAX($J13,1),220),CURVAS_KC!$A$5:$A$224,0),MATCH($Z13,CURVAS_KC!$B$4:$J$4,0)),"PENDENTE"))) | L13: =IF($G13="","",$G13) | M13: =IF($L13="","",SUMIFS(ETO_SEMANAL!$B$6:$B$65,ETO_SEMANAL!$A$6:$A$65,">"&$L13,ETO_SEMANAL!$A$6:$A$65,"<="&DATA_REF)) | N13: =IF($L13="","",SUMIFS(ETO_SEMANAL!$C$6:$C$65,ETO_SEMANAL!$A$6:$A$65,">"&$L13,ETO_SEMANAL!$A$6:$A$65,"<="&DATA_REF)) | O13: =IF(OR($K13="",$K13="PENDENTE",$M13=""),"",$K13*$M13) | P13: =IF($O13="","",MAX(0,$O13-N($N13))) | Q13: =IF($P13="","",$P13/EF_APLIC) | S13: =IF(OR($AA13="",$R13=""),"",IFERROR(INDEX(LAMINA_HORA!$C$5:$V$114,MATCH($AA13,LAMINA_HORA!$A$5:$A$114,0),MATCH($R13,LAMINA_HORA!$C$3:$V$3,0)),"?")) | T13: =IF(OR($AA13="",$R13=""),"",IFERROR(INDEX(LAMINA_HORA!$W$5:$AP$114,MATCH($AA13,LAMINA_HORA!$A$5:$A$114,0),MATCH($R13,LAMINA_HORA!$W$3:$AP$3,0)),"?")) | U13: 0.449 | V13: =IF(OR($S13="",$S13="?",$F13=""),"",$S13*$F13*10) | W13: =IF(OR($V13="",$U13=""),"",$V13*$U13) | X13: =IF($K13="PENDENTE","Definir Kc",IF($P13="","-",IF($P13>=TURNO,"IRRIGAR",IF($P13>=TURNO*FRAC_ACOMP,"Acompanhar","Aguardar")))) | Y13: =IF(OR($P13="",$P13=0),"-",IF($P13>=2*TURNO,"Alta",IF($P13>=TURNO,"Media","Baixa"))) | Z13: CACAU | AA13: P31
A14: Pivô 32 | B14: Modulo 1 | C14: C3Z3/R7 | D14: PS1319/FA13/CCN51 | F14: 133 | G14: 45923 | H14: =IF(OR($G14="",$G14>DATA_REF),"NAO","SIM") | I14: =IF(OR($G14="",$G14>DATA_REF),"",DATA_REF-$G14) | J14: =IF($I14="","",MAX(0,$I14-0)) | K14: =IF($Z14="","PENDENTE",IF($I14="","",IFERROR(INDEX(CURVAS_KC!$B$5:$J$224,MATCH(MIN(MAX($J14,1),220),CURVAS_KC!$A$5:$A$224,0),MATCH($Z14,CURVAS_KC!$B$4:$J$4,0)),"PENDENTE"))) | L14: =IF($G14="","",$G14) | M14: =IF($L14="","",SUMIFS(ETO_SEMANAL!$B$6:$B$65,ETO_SEMANAL!$A$6:$A$65,">"&$L14,ETO_SEMANAL!$A$6:$A$65,"<="&DATA_REF)) | N14: =IF($L14="","",SUMIFS(ETO_SEMANAL!$C$6:$C$65,ETO_SEMANAL!$A$6:$A$65,">"&$L14,ETO_SEMANAL!$A$6:$A$65,"<="&DATA_REF)) | O14: =IF(OR($K14="",$K14="PENDENTE",$M14=""),"",$K14*$M14) | P14: =IF($O14="","",MAX(0,$O14-N($N14))) | Q14: =IF($P14="","",$P14/EF_APLIC) | S14: =IF(OR($AA14="",$R14=""),"",IFERROR(INDEX(LAMINA_HORA!$C$5:$V$114,MATCH($AA14,LAMINA_HORA!$A$5:$A$114,0),MATCH($R14,LAMINA_HORA!$C$3:$V$3,0)),"?")) | T14: =IF(OR($AA14="",$R14=""),"",IFERROR(INDEX(LAMINA_HORA!$W$5:$AP$114,MATCH($AA14,LAMINA_HORA!$A$5:$A$114,0),MATCH($R14,LAMINA_HORA!$W$3:$AP$3,0)),"?")) | U14: 0.446 | V14: =IF(OR($S14="",$S14="?",$F14=""),"",$S14*$F14*10) | W14: =IF(OR($V14="",$U14=""),"",$V14*$U14) | X14: =IF($K14="PENDENTE","Definir Kc",IF($P14="","-",IF($P14>=TURNO,"IRRIGAR",IF($P14>=TURNO*FRAC_ACOMP,"Acompanhar","Aguardar")))) | Y14: =IF(OR($P14="",$P14=0),"-",IF($P14>=2*TURNO,"Alta",IF($P14>=TURNO,"Media","Baixa"))) | Z14: CACAU | AA14: P32
A15: Pivô 34 | B15: Modulo 1 | C15: C3Z3/R7 | D15: PS1319/FA13/CCN51 | F15: 150 | G15: 46326 | H15: =IF(OR($G15="",$G15>DATA_REF),"NAO","SIM") | I15: =IF(OR($G15="",$G15>DATA_REF),"",DATA_REF-$G15) | J15: =IF($I15="","",MAX(0,$I15-0)) | K15: =IF($Z15="","PENDENTE",IF($I15="","",IFERROR(INDEX(CURVAS_KC!$B$5:$J$224,MATCH(MIN(MAX($J15,1),220),CURVAS_KC!$A$5:$A$224,0),MATCH($Z15,CURVAS_KC!$B$4:$J$4,0)),"PENDENTE"))) | L15: =IF($G15="","",$G15) | M15: =IF($L15="","",SUMIFS(ETO_SEMANAL!$B$6:$B$65,ETO_SEMANAL!$A$6:$A$65,">"&$L15,ETO_SEMANAL!$A$6:$A$65,"<="&DATA_REF)) | N15: =IF($L15="","",SUMIFS(ETO_SEMANAL!$C$6:$C$65,ETO_SEMANAL!$A$6:$A$65,">"&$L15,ETO_SEMANAL!$A$6:$A$65,"<="&DATA_REF)) | O15: =IF(OR($K15="",$K15="PENDENTE",$M15=""),"",$K15*$M15) | P15: =IF($O15="","",MAX(0,$O15-N($N15))) | Q15: =IF($P15="","",$P15/EF_APLIC) | S15: =IF(OR($AA15="",$R15=""),"",IFERROR(INDEX(LAMINA_HORA!$C$5:$V$114,MATCH($AA15,LAMINA_HORA!$A$5:$A$114,0),MATCH($R15,LAMINA_HORA!$C$3:$V$3,0)),"?")) | T15: =IF(OR($AA15="",$R15=""),"",IFERROR(INDEX(LAMINA_HORA!$W$5:$AP$114,MATCH($AA15,LAMINA_HORA!$A$5:$A$114,0),MATCH($R15,LAMINA_HORA!$W$3:$AP$3,0)),"?")) | U15: 0.461 | V15: =IF(OR($S15="",$S15="?",$F15=""),"",$S15*$F15*10) | W15: =IF(OR($V15="",$U15=""),"",$V15*$U15) | X15: =IF($K15="PENDENTE","Definir Kc",IF($P15="","-",IF($P15>=TURNO,"IRRIGAR",IF($P15>=TURNO*FRAC_ACOMP,"Acompanhar","Aguardar")))) | Y15: =IF(OR($P15="",$P15=0),"-",IF($P15>=2*TURNO,"Alta",IF($P15>=TURNO,"Media","Baixa"))) | Z15: CACAU | AA15: P34
A16: Pivô 75 | B16: Modulo 1 | C16: C3Z3/R7 | D16: PS1319/FA13/CCN51 | F16: 9 | G16: 45923 | H16: =IF(OR($G16="",$G16>DATA_REF),"NAO","SIM") | I16: =IF(OR($G16="",$G16>DATA_REF),"",DATA_REF-$G16) | J16: =IF($I16="","",MAX(0,$I16-0)) | K16: =IF($Z16="","PENDENTE",IF($I16="","",IFERROR(INDEX(CURVAS_KC!$B$5:$J$224,MATCH(MIN(MAX($J16,1),220),CURVAS_KC!$A$5:$A$224,0),MATCH($Z16,CURVAS_KC!$B$4:$J$4,0)),"PENDENTE"))) | L16: =IF($G16="","",$G16) | M16: =IF($L16="","",SUMIFS(ETO_SEMANAL!$B$6:$B$65,ETO_SEMANAL!$A$6:$A$65,">"&$L16,ETO_SEMANAL!$A$6:$A$65,"<="&DATA_REF)) | N16: =IF($L16="","",SUMIFS(ETO_SEMANAL!$C$6:$C$65,ETO_SEMANAL!$A$6:$A$65,">"&$L16,ETO_SEMANAL!$A$6:$A$65,"<="&DATA_REF)) | O16: =IF(OR($K16="",$K16="PENDENTE",$M16=""),"",$K16*$M16) | P16: =IF($O16="","",MAX(0,$O16-N($N16))) | Q16: =IF($P16="","",$P16/EF_APLIC) | S16: =IF(OR($AA16="",$R16=""),"",IFERROR(INDEX(LAMINA_HORA!$C$5:$V$114,MATCH($AA16,LAMINA_HORA!$A$5:$A$114,0),MATCH($R16,LAMINA_HORA!$C$3:$V$3,0)),"?")) | T16: =IF(OR($AA16="",$R16=""),"",IFERROR(INDEX(LAMINA_HORA!$W$5:$AP$114,MATCH($AA16,LAMINA_HORA!$A$5:$A$114,0),MATCH($R16,LAMINA_HORA!$W$3:$AP$3,0)),"?")) | U16: 0.305 | V16: =IF(OR($S16="",$S16="?",$F16=""),"",$S16*$F16*10) | W16: =IF(OR($V16="",$U16=""),"",$V16*$U16) | X16: =IF($K16="PENDENTE","Definir Kc",IF($P16="","-",IF($P16>=TURNO,"IRRIGAR",IF($P16>=TURNO*FRAC_ACOMP,"Acompanhar","Aguardar")))) | Y16: =IF(OR($P16="",$P16=0),"-",IF($P16>=2*TURNO,"Alta",IF($P16>=TURNO,"Media","Baixa"))) | Z16: CACAU | AA16: P75
A17: Pivô 76 | B17: Modulo 1 | C17: C3Z3/R7 | D17: PS1319/FA13/CCN51 | F17: 84 | G17: 45923 | H17: =IF(OR($G17="",$G17>DATA_REF),"NAO","SIM") | I17: =IF(OR($G17="",$G17>DATA_REF),"",DATA_REF-$G17) | J17: =IF($I17="","",MAX(0,$I17-0)) | K17: =IF($Z17="","PENDENTE",IF($I17="","",IFERROR(INDEX(CURVAS_KC!$B$5:$J$224,MATCH(MIN(MAX($J17,1),220),CURVAS_KC!$A$5:$A$224,0),MATCH($Z17,CURVAS_KC!$B$4:$J$4,0)),"PENDENTE"))) | L17: =IF($G17="","",$G17) | M17: =IF($L17="","",SUMIFS(ETO_SEMANAL!$B$6:$B$65,ETO_SEMANAL!$A$6:$A$65,">"&$L17,ETO_SEMANAL!$A$6:$A$65,"<="&DATA_REF)) | N17: =IF($L17="","",SUMIFS(ETO_SEMANAL!$C$6:$C$65,ETO_SEMANAL!$A$6:$A$65,">"&$L17,ETO_SEMANAL!$A$6:$A$65,"<="&DATA_REF)) | O17: =IF(OR($K17="",$K17="PENDENTE",$M17=""),"",$K17*$M17) | P17: =IF($O17="","",MAX(0,$O17-N($N17))) | Q17: =IF($P17="","",$P17/EF_APLIC) | S17: =IF(OR($AA17="",$R17=""),"",IFERROR(INDEX(LAMINA_HORA!$C$5:$V$114,MATCH($AA17,LAMINA_HORA!$A$5:$A$114,0),MATCH($R17,LAMINA_HORA!$C$3:$V$3,0)),"?")) | T17: =IF(OR($AA17="",$R17=""),"",IFERROR(INDEX(LAMINA_HORA!$W$5:$AP$114,MATCH($AA17,LAMINA_HORA!$A$5:$A$114,0),MATCH($R17,LAMINA_HORA!$W$3:$AP$3,0)),"?")) | U17: 0.305 | V17: =IF(OR($S17="",$S17="?",$F17=""),"",$S17*$F17*10) | W17: =IF(OR($V17="",$U17=""),"",$V17*$U17) | X17: =IF($K17="PENDENTE","Definir Kc",IF($P17="","-",IF($P17>=TURNO,"IRRIGAR",IF($P17>=TURNO*FRAC_ACOMP,"Acompanhar","Aguardar")))) | Y17: =IF(OR($P17="",$P17=0),"-",IF($P17>=2*TURNO,"Alta",IF($P17>=TURNO,"Media","Baixa"))) | Z17: CACAU | AA17: P76
A18: Nec BRUTA (azul) = lamina bruta ACUMULADA desde a ultima irrigacao (soma das ETos semanais x Kc, menos chuva, /0,90). Ao irrigar, atualize 'Ult.irrig'. So aparecem pivos plantados; preencha a Data plantio para um novo pivo e use Dados>Reaplicar.

Sheet MILHO
A1: MILHO 26/27 - manejo
A2: So pivos PLANTADOS (filtro Plantado=SIM). Avisar plantio = preencher Data plantio. Emergencia 0 dias. ETc=Kc(DAE)xETo semanal.
A4: Pivo | B4: Modulo | C4: Casa b. | D4: Variedade | E4: Classe | F4: Area(ha) | G4: Data plantio | H4: Plantado? | I4: DAP | J4: DAE | K4: Kc | L4: Ult.irrig | M4: ETo acum | N4: Chuva acum | O4: ETc acum | P4: Nec liq (mm) | Q4: Nec BRUTA (mm) | R4: % aplic | S4: Lamina(mm) | T4: Horas | U4: CE(kWh/m3) | V4: Volume(m3) | W4: Energia(kWh) | X4: Decisao | Y4: Prioridade | Z4: Curva Kc | AA4: Cod
A5: Nec BRUTA (azul) = lamina bruta ACUMULADA desde a ultima irrigacao (soma das ETos semanais x Kc, menos chuva, /0,90). Ao irrigar, atualize 'Ult.irrig'. So aparecem pivos plantados; preencha a Data plantio para um novo pivo e use Dados>Reaplicar.

Sheet ENERGIA_MODULO
A1: ENERGIA POR MODULO - conforme a quantidade de pivos irrigando
A2: Soma automatica dos pivos que estao com % preenchido (irrigando) em todas as culturas. CE = captacao do modulo + pressurizacao.
A4: Modulo | B4: Pivos irrigando | C4: Volume (m3) | D4: Energia (kWh) | E4: Observacao
A5: Modulo 1 | B5: =COUNTIFS(SOJA!$B$5:$B$300,$A5,SOJA!$R$5:$R$300,">0")+COUNTIFS(ALGODAO!$B$5:$B$300,$A5,ALGODAO!$R$5:$R$300,">0")+COUNTIFS(TABACO!$B$5:$B$300,$A5,TABACO!$R$5:$R$300,">0")+COUNTIFS(CACAU!$B$5:$B$300,$A5,CACAU!$R$5:$R$300,">0")+COUNTIFS(MILHO!$B$5:$B$300,$A5,MILHO!$R$5:$R$300,">0") | C5: =SUMIFS(SOJA!$V$5:$V$300,SOJA!$B$5:$B$300,$A5)+SUMIFS(ALGODAO!$V$5:$V$300,ALGODAO!$B$5:$B$300,$A5)+SUMIFS(TABACO!$V$5:$V$300,TABACO!$B$5:$B$300,$A5)+SUMIFS(CACAU!$V$5:$V$300,CACAU!$B$5:$B$300,$A5)+SUMIFS(MILHO!$V$5:$V$300,MILHO!$B$5:$B$300,$A5) | D5: =SUMIFS(SOJA!$W$5:$W$300,SOJA!$B$5:$B$300,$A5)+SUMIFS(ALGODAO!$W$5:$W$300,ALGODAO!$B$5:$B$300,$A5)+SUMIFS(TABACO!$W$5:$W$300,TABACO!$B$5:$B$300,$A5)+SUMIFS(CACAU!$W$5:$W$300,CACAU!$B$5:$B$300,$A5)+SUMIFS(MILHO!$W$5:$W$300,MILHO!$B$5:$B$300,$A5)
A6: Modulo 2 | B6: =COUNTIFS(SOJA!$B$5:$B$300,$A6,SOJA!$R$5:$R$300,">0")+COUNTIFS(ALGODAO!$B$5:$B$300,$A6,ALGODAO!$R$5:$R$300,">0")+COUNTIFS(TABACO!$B$5:$B$300,$A6,TABACO!$R$5:$R$300,">0")+COUNTIFS(CACAU!$B$5:$B$300,$A6,CACAU!$R$5:$R$300,">0")+COUNTIFS(MILHO!$B$5:$B$300,$A6,MILHO!$R$5:$R$300,">0") | C6: =SUMIFS(SOJA!$V$5:$V$300,SOJA!$B$5:$B$300,$A6)+SUMIFS(ALGODAO!$V$5:$V$300,ALGODAO!$B$5:$B$300,$A6)+SUMIFS(TABACO!$V$5:$V$300,TABACO!$B$5:$B$300,$A6)+SUMIFS(CACAU!$V$5:$V$300,CACAU!$B$5:$B$300,$A6)+SUMIFS(MILHO!$V$5:$V$300,MILHO!$B$5:$B$300,$A6) | D6: =SUMIFS(SOJA!$W$5:$W$300,SOJA!$B$5:$B$300,$A6)+SUMIFS(ALGODAO!$W$5:$W$300,ALGODAO!$B$5:$B$300,$A6)+SUMIFS(TABACO!$W$5:$W$300,TABACO!$B$5:$B$300,$A6)+SUMIFS(CACAU!$W$5:$W$300,CACAU!$B$5:$B$300,$A6)+SUMIFS(MILHO!$W$5:$W$300,MILHO!$B$5:$B$300,$A6)
A7: Modulo 3 | B7: =COUNTIFS(SOJA!$B$5:$B$300,$A7,SOJA!$R$5:$R$300,">0")+COUNTIFS(ALGODAO!$B$5:$B$300,$A7,ALGODAO!$R$5:$R$300,">0")+COUNTIFS(TABACO!$B$5:$B$300,$A7,TABACO!$R$5:$R$300,">0")+COUNTIFS(CACAU!$B$5:$B$300,$A7,CACAU!$R$5:$R$300,">0")+COUNTIFS(MILHO!$B$5:$B$300,$A7,MILHO!$R$5:$R$300,">0") | C7: =SUMIFS(SOJA!$V$5:$V$300,SOJA!$B$5:$B$300,$A7)+SUMIFS(ALGODAO!$V$5:$V$300,ALGODAO!$B$5:$B$300,$A7)+SUMIFS(TABACO!$V$5:$V$300,TABACO!$B$5:$B$300,$A7)+SUMIFS(CACAU!$V$5:$V$300,CACAU!$B$5:$B$300,$A7)+SUMIFS(MILHO!$V$5:$V$300,MILHO!$B$5:$B$300,$A7) | D7: =SUMIFS(SOJA!$W$5:$W$300,SOJA!$B$5:$B$300,$A7)+SUMIFS(ALGODAO!$W$5:$W$300,ALGODAO!$B$5:$B$300,$A7)+SUMIFS(TABACO!$W$5:$W$300,TABACO!$B$5:$B$300,$A7)+SUMIFS(CACAU!$W$5:$W$300,CACAU!$B$5:$B$300,$A7)+SUMIFS(MILHO!$W$5:$W$300,MILHO!$B$5:$B$300,$A7)
A8: RDM | B8: =COUNTIFS(SOJA!$B$5:$B$300,$A8,SOJA!$R$5:$R$300,">0")+COUNTIFS(ALGODAO!$B$5:$B$300,$A8,ALGODAO!$R$5:$R$300,">0")+COUNTIFS(TABACO!$B$5:$B$300,$A8,TABACO!$R$5:$R$300,">0")+COUNTIFS(CACAU!$B$5:$B$300,$A8,CACAU!$R$5:$R$300,">0")+COUNTIFS(MILHO!$B$5:$B$300,$A8,MILHO!$R$5:$R$300,">0") | C8: =SUMIFS(SOJA!$V$5:$V$300,SOJA!$B$5:$B$300,$A8)+SUMIFS(ALGODAO!$V$5:$V$300,ALGODAO!$B$5:$B$300,$A8)+SUMIFS(TABACO!$V$5:$V$300,TABACO!$B$5:$B$300,$A8)+SUMIFS(CACAU!$V$5:$V$300,CACAU!$B$5:$B$300,$A8)+SUMIFS(MILHO!$V$5:$V$300,MILHO!$B$5:$B$300,$A8) | D8: =SUMIFS(SOJA!$W$5:$W$300,SOJA!$B$5:$B$300,$A8)+SUMIFS(ALGODAO!$W$5:$W$300,ALGODAO!$B$5:$B$300,$A8)+SUMIFS(TABACO!$W$5:$W$300,TABACO!$B$5:$B$300,$A8)+SUMIFS(CACAU!$W$5:$W$300,CACAU!$B$5:$B$300,$A8)+SUMIFS(MILHO!$W$5:$W$300,MILHO!$B$5:$B$300,$A8)
A9: TOTAL | B9: =SUM($B$5:$B$8) | C9: =SUM($C$5:$C$8) | D9: =SUM($D$5:$D$8)
A11: Um pivo entra na conta quando voce preenche o % (percentimetro) na aba da cultura. Energia = Volume (lamina x area x 10) x CE do pivo (captacao do modulo + pressurizacao). CE em kWh/m3.

Sheet ETO_SEMANAL
A1: ETO_SEMANAL - clima por semana (ATUALIZAR TODA SEMANA)
A2: Chuva da semana atual (mm): | B2: =IFERROR(INDEX(ETO_SEMANAL!$C$6:$C$65,MATCH(DATA_REF,ETO_SEMANAL!$A$6:$A$65,1)),"")
A3: ETo da semana atual (mm): | B3: =IFERROR(INDEX(ETO_SEMANAL!$B$6:$B$65,MATCH(DATA_REF,ETO_SEMANAL!$A$6:$A$65,1)),"")
A5: Semana (inicio) | B5: ETo (mm/sem) | C5: Chuva (mm/sem) | D5: Obs
A6: 46265
A7: 46272
A8: 46279
A9: 46286
A10: 46293
A11: 46300
A12: 46307
A13: 46314
A14: 46321
A15: 46328
A16: 46335
A17: 46342
... A65: 46678

Sheet CURVAS_KC
A1: CURVAS_KC - Kc diario por cultura/classe (LINEAR, por DAE)
A2: Algodao: arquivo. Soja/milho: por fase. Tabaco/cacau: literatura FAO-56.
A4: DAE | B4: ALG_PRECOCE | C4: ALG_MEDIO | D4: ALG_TARDIO | E4: SOJA_PRECOCE | F4: SOJA_MEDIA | G4: SOJA_TARDIA | H4: MILHO | I4: TABACO | J4: CACAU
A5: 1 | B5: 0.35 | C5: 0.35 | D5: 0.35 | E5: 0.4 | F5: 0.4 | G5: 0.4 | H5: 0.3 | I5: 0.35 | J5: 1
A6: 2 | B6: 0.35 | C6: 0.35 | D6: 0.35 | E6: 0.4 | F6: 0.4 | G6: 0.4 | H6: 0.3 | I6: 0.35 | J6: 1
A7: 3 | B7: 0.35 | C7: 0.35 | D7: 0.35 | E7: 0.4 | F7: 0.4 | G7: 0.4 | H7: 0.3 | I7: 0.35 | J7: 1
A8: 4 | B8: 0.35 | C8: 0.35 | D8: 0.35 | E8: 0.4 | F8: 0.4 | G8: 0.4 | H8: 0.3 | I8: 0.35 | J8: 1
A9: 5 | B9: 0.35 | C9: 0.35 | D9: 0.35 | E9: 0.4 | F9: 0.4 | G9: 0.4 | H9: 0.3 | I9: 0.35 | J9: 1
A10: 6 | B10: 0.35 | C10: 0.35 | D10: 0.35 | E10: 0.4 | F10: 0.4 | G10: 0.4 | H10: 0.3 | I10: 0.35 | J10: 1
A11: 7 | B11: 0.35 | C11: 0.35 | D11: 0.35 | E11: 0.4 | F11: 0.4 | G11: 0.4 | H11: 0.3 | I11: 0.35 | J11: 1
A12: 8 | B12: 0.35 | C12: 0.35 | D12: 0.35 | E12: 0.4 | F12: 0.4 | G12: 0.4 | H12: 0.3 | I12: 0.35 | J12: 1
A13: 9 | B13: 0.35 | C13: 0.35 | D13: 0.35 | E13: 0.4 | F13: 0.4 | G13: 0.4 | H13: 0.3 | I13: 0.35 | J13: 1
A14: 10 | B14: 0.35 | C14: 0.35 | D14: 0.35 | E14: 0.4 | F14: 0.4 | G14: 0.4 | H14: 0.3 | I14: 0.35 | J14: 1
A15: 11 | B15: 0.35 | C15: 0.35 | D15: 0.35 | E15: 0.4 | F15: 0.4 | G15: 0.4 | H15: 0.3 | I15: 0.35 | J15: 1
A16: 12 | B16: 0.35 | C16: 0.35 | D16: 0.35 | E16: 0.4 | F16: 0.4 | G16: 0.4 | H16: 0.3 | I16: 0.35 | J16: 1
... A224: 220 | B224: 0.6 | C224: 0.6 | D224: 0.6 | E224: 0.5 | F224: 0.5 | G224: 0.5 | H224: 0.6 | I224: 0.9 | J224: 1

Sheet LAMINA_HORA
A1: LAMINA_HORA - lamina (mm) e horas por percentimetro (importado)
A2: Usado nas abas de cultura.
C3: 100 | D3: 95 | E3: 90 | F3: 85 | G3: 80 | H3: 75 | I3: 70 | J3: 65 | K3: 60 | L3: 55 | M3: 50 | N3: 45 | O3: 40 | P3: 35 | Q3: 30 | R3: 25 | S3: 20 | T3: 15 | U3: 10 | V3: 5 | W3: 100 | X3: 95 | Y3: 90 | Z3: 85 | AA3: 80 | AB3: 75 | AC3: 70 | AD3: 65 | AE3: 60 | AF3: 55 | AG3: 50 | AH3: 45 | AI3: 40 | AJ3: 35 | AK3: 30 | AL3: 25 | AM3: 20 | AN3: 15 | AO3: 10 | AP3: 5
A4: Cod | B4: Faz | C4: L100 | D4: L95 | E4: L90 | F4: L85 | G4: L80 | H4: L75 | I4: L70 | J4: L65 | K4: L60 | L4: L55 | M4: L50 | N4: L45 | O4: L40 | P4: L35 | Q4: L30 | R4: L25 | S4: L20 | T4: L15 | U4: L10 | V4: L5 | W4: H100 | X4: H95 | Y4: H90 | Z4: H85 | AA4: H80 | AB4: H75 | AC4: H70 | AD4: H65 | AE4: H60 | AF4: H55 | AG4: H50 | AH4: H45 | AI4: H40 | AJ4: H35 | AK4: H30 | AL4: H25 | AM4: H20 | AN4: H15 | AO4: H10 | AP4: H5
A5: PA | B5: Karitel | C5: 6.06 | D5: 6.3789474 | E5: 6.7333333 | F5: 7.1294118 | G5: 7.575 | H5: 8.08 | I5: 8.6571429 | J5: 9.3230769 | K5: 10.1 | L5: 11.018182 | M5: 12.12 | N5: 13.466667 | O5: 15.15 | P5: 17.314286 | Q5: 20.2 | R5: 24.24 | S5: 30.3 | T5: 40.4 | U5: 60.6 | V5: 121.2 | W5: 13.54 | X5: 14.252632 | Y5: 15.044444 | Z5: 15.929412 | AA5: 16.925 | AB5: 18.053333 | AC5: 19.342857 | AD5: 20.830769 | AE5: 22.566667 | AF5: 24.618182 | AG5: 27.08 | AH5: 30.088889 | AI5: 33.85 | AJ5: 38.685714 | AK5: 45.133333 | AL5: 54.16 | AM5: 67.7 | AN5: 90.266667 | AO5: 135.4 | AP5: 270.8
A6: PB | B6: Karitel | C6: 6.06 | D6: 6.3789474 | E6: 6.7333333 | F6: 7.1294118 | G6: 7.575 | H6: 8.08 | I6: 8.6571429 | J6: 9.3230769 | K6: 10.1 | L6: 11.018182 | M6: 12.12 | N6: 13.466667 | O6: 15.15 | P6: 17.314286 | Q6: 20.2 | R6: 24.24 | S6: 30.3 | T6: 40.4 | U6: 60.6 | V6: 121.2 | W6: 13.54 | X6: 14.252632 | Y6: 15.044444 | Z6: 15.929412 | AA6: 16.925 | AB6: 18.053333 | AC6: 19.342857 | AD6: 20.830769 | AE6: 22.566667 | AF6: 24.618182 | AG6: 27.08 | AH6: 30.088889 | AI6: 33.85 | AJ6: 38.685714 | AK6: 45.133333 | AL6: 54.16 | AM6: 67.7 | AN6: 90.266667 | AO6: 135.4 | AP6: 270.8
A7: P1 | B7: Karitel | C7: 5.61 | D7: 5.9052632 | E7: 6.2333333 | F7: 6.6 | G7: 7.0125 | H7: 7.48 | I7: 8.0142857 | J7: 8.6307692 | K7: 9.35 | L7: 10.2 | M7: 11.22 | N7: 12.466667 | O7: 14.025 | P7: 16.028571 | Q7: 18.7 | R7: 22.44 | S7: 28.05 | T7: 37.4 | U7: 56.1 | V7: 112.2 | W7: 15.11 | X7: 15.905263 | Y7: 16.788889 | Z7: 17.776471 | AA7: 18.8875 | AB7: 20.146667 | AC7: 21.585714 | AD7: 23.246154 | AE7: 25.183333 | AF7: 27.472727 | AG7: 30.22 | AH7: 33.577778 | AI7: 37.775 | AJ7: 43.171429 | AK7: 50.366667 | AL7: 60.44 | AM7: 75.55 | AN7: 100.73333 | AO7: 151.1 | AP7: 302.2
