Workbook

Sheet LEIA-ME
B2: SIMULADOR DE GESTAO DE AGUA DA SAFRA - UNIDADE RDM
B3: Modelo de capacidade hidrica e operacional. Filtrado so para a RDM (inclui a nova casa RM08); Karitel e demais unidades nao entram em nenhum calculo.
B5: O QUE ESTA PASTA RESPONDE
B6: - Onde e quando vai faltar agua na safra, por casa de bomba (PAINEL_GESTAO).
B7: - Quanto cada cultura, pivo, casa e trecho demanda, semana a semana.
B8: - Se a infraestrutura cabe nas 21 h/dia e onde esta o gargalo.
B9: - Quanto a chuva util cobre e quanto sobra para a irrigacao.
B11: ONDE MEXER (celulas amarelas, texto azul)
B12: - PARAMETROS_GERAIS: horas/dia, horas de captacao, eficiencia, fator de chuva util, faixas de alerta.
B13: - CADASTRO_PIVOS: area, lamina nominal, vazao de projeto e eficiencia de cada pivo.
B14: - CADASTRO_CASAS_BOMBA: vazao operacional de recalque de cada casa.
B15: - CADASTRO_TRECHOS_CANAL: capacidade dos trechos e matriz TRECHO x CASA.
... B33: Fontes: STC_RDM REV10 (casas, pivos, areas, pocos, reservacao, captacao, lamina) e rotacao bienal 26-28 v.21 (abas Rotacao + Rotacao Milho semente), FAZENDA = RDM, Irrigado.

Sheet DASHBOARD_RDM
B2: DASHBOARD RDM - planejamento hidrico da safra
B3: Todos os numeros abaixo sao formulas. Mude plantio, ETo, chuva, Kc, vazao ou horas e o painel inteiro se refaz.
B5: Area irrigada cadastrada | F5: Area irrigada ativa no pico | J5: Demanda ETc da safra | N5: Demanda ETc da safra
B6: =SUM(CADASTRO_PIVOS!$E$6:$E$41) -> 4351.08 | D6: ha | F6: =MAX(AUX_MATRIZES!$C$141:$BP$141) -> 3826.41 | H6: ha | J6: =IFERROR(SUM(PLANEJAMENTO_SEMANAL!$AG$6:$AG$2381)/SUM(CADASTRO_PIVOS!$E$6:$E$41),0) -> 1044.9769 | L6: mm | N6: =SUM(PLANEJAMENTO_SEMANAL!$AG$6:$AG$2381)*MM_PARA_M3_HA -> 45467782 | P6: m3
B9: Chuva util da safra | F9: Chuva util da safra | J9: Irrigacao liquida necessaria | N9: Irrigacao liquida necessaria
B10: =IFERROR(SUM(PLANEJAMENTO_SEMANAL!$AH$6:$AH$2381)/SUM(CADASTRO_PIVOS!$E$6:$E$41),0) -> 726.45544 | D10: mm | F10: =SUM(PLANEJAMENTO_SEMANAL!$AH$6:$AH$2381)*MM_PARA_M3_HA -> 31608657 | H10: m3 | J10: =IFERROR(SUM(PLANEJAMENTO_SEMANAL!$AI$6:$AI$2381)/SUM(CADASTRO_PIVOS!$E$6:$E$41),0) -> 490.00495 | L10: mm | N10: =SUM(PLANEJAMENTO_SEMANAL!$AI$6:$AI$2381)*MM_PARA_M3_HA -> 21320508 | P10: m3
B13: Irrigacao bruta necessaria | F13: Irrigacao bruta (VOLUME TOTAL DA SAFRA) | J13: Pico de demanda | N13: Pico de vazao requerida
B14: =IFERROR(SUM(PLANEJAMENTO_SEMANAL!$Z$6:$Z$2381)/(SUM(CADASTRO_PIVOS!$E$6:$E$41)*MM_PARA_M3_HA),0) -> 576.47642 | D14: mm | F14: =SUM(PLANEJAMENTO_SEMANAL!$Z$6:$Z$2381) -> 25082950 | H14: m3 | J14: =MAX(AUX_MATRIZES!$C$154:$BP$154) -> 170974.79 | L14: m3/dia | N14: =MAX(AUX_MATRIZES!$C$155:$BP$155) -> 8141.6568 | P14: m3/h
B17: Capacidade instalada do sistema | F17: Semana critica | J17: Data da semana critica | N17: Casa de bomba mais critica
B18: =MAX(AUX_MATRIZES!$C$156:$BP$156) -> 30413.729 | D18: m3/h | F18: =IFERROR(INDEX(CAPACIDADE_21H!$B$6:$B$71,MATCH(MAX(CAPACIDADE_21H!$E$6:$E$71),CAPACIDADE_21H!$E$6:$E$71,0)),"-") -> 36 | H18: semana | J18: =IFERROR(INDEX(CAPACIDADE_21H!$C$6:$C$71,MATCH(MAX(CAPACIDADE_21H!$E$6:$E$71),CAPACIDADE_21H!$E$6:$E$71,0)),"-") -> 46510 | L18: data | N18: =IFERROR(INDEX(AUX_MATRIZES!$B$56:$B$63,MATCH(MAX(AUX_MATRIZES!$BQ$56:$BQ$63),AUX_MATRIZES!$BQ$56:$BQ$63,0)),"-") -> RM03 | P18: casa
B21: Trecho de canal mais critico | F21: Maior utilizacao hidraulica (sistema) | J21: Maior utilizacao de uma casa de bomba | N21: Maior utilizacao de um trecho
B22: =IFERROR(INDEX(AUX_MATRIZES!$B$116:$B$123,MATCH(MAX(AUX_MATRIZES!$BQ$116:$BQ$123),AUX_MATRIZES!$BQ$116:$BQ$123,0)),"-") -> TR03 | D22: trecho | F22: =MAX(AUX_MATRIZES!$C$157:$BP$157) -> 0.26769677 | H22: % | J22: =MAX(AUX_MATRIZES!$BQ$56:$BQ$63) -> 0.35292952 | L22: % | N22: =MAX(AUX_MATRIZES!$BQ$116:$BQ$123) -> 0.35292952 | P22: %
B25: Maior utilizacao de um pivo | F25: Semanas inviaveis em 21 h/dia | J25: Horas totais de irrigacao na safra | N25: Casas de bomba com captacao insuficiente
B26: =MAX(AUX_MATRIZES!$C$148:$BP$148) -> 0.55746606 | D26: % | F26: =COUNTIF(CAPACIDADE_21H!$G$6:$G$71,">"&LIMITE_CRITICO) -> 0 | H26: semanas | J26: =SUM(PLANEJAMENTO_SEMANAL!$AB$6:$AB$2381) -> 29176.857 | L26: h | N26: =PAINEL_GESTAO!$F$16 -> 3 | P26: de 8
B29: Volume total faltante na safra
B30: =PAINEL_GESTAO!$F$18 -> 2913026.7 | D30: m3
B33: RESPOSTA DO MODELO
B34: ="GESTAO DE AGUA - "&IF(PAINEL_GESTAO!$F$16=0,"a captacao atende o consumo nas 8 casas o ano todo.","a captacao NAO acompanha o consumo em "&PAINEL_GESTAO!$F$16&" casa(s). A mais critica e "&PAINEL_GESTAO!$F$19&", com "&TEXT(PAINEL_GESTAO!$F$18,"#,##0")&" m3 faltantes na safra. Detalhe em PAINEL_GESTAO.")&" | PIVOS EM 21 h/dia - cabem com folga: utilizacao maxima de "&TEXT(MAX(PLANEJAMENTO_SEMANAL!$AD$6:$AD$2381),"0.0%")&". O gargalo da RDM esta na captacao/reservatorio, nao nas horas de pivo." -> GESTAO DE AGUA - a captacao NAO acompanha o consumo em 3 casa(s). A mais critica e RM07, com 2,913,027 m3 faltantes na safra. Detalhe em PAINEL_GESTAO. | PIVOS EM 21 h/dia - cabem com folga: utilizacao maxima de 55.7%. O gargalo da RDM esta na captacao/reservatorio, nao nas horas de pivo.
B37: ATENCAO: enquanto ETo, chuva util, eficiencia, vazao operacional das casas e capacidade dos trechos forem DADO PENDENTE (ver PENDENCIAS_CADASTRO), os numeros sao ordem de grandeza, nao compromisso.

Sheet PAINEL_GESTAO
B2: PAINEL DE GESTAO DE AGUA - onde e quando vai faltar
B3: Diagnostico por casa de bomba, a partir do balanco diario. Em quais casas e dias a captacao nao acompanha o consumo, quanto falta e o que fazer.
B5: Casa de bomba | C5: Captacao (m3/dia) | D5: Consumo de pico (m3/dia) | E5: Dias com falta de agua | F5: Primeiro dia de falta | G5: Ultimo dia de falta | H5: Volume total faltante (m3) | I5: Maior falta em um dia (m3) | J5: Horas extras de captacao no pico (h/dia) | K5: Vazao adicional necessaria (m3/h) | L5: Situacao | M5: Recomendacao
B6: =CADASTRO_CASAS_BOMBA!$B$6 -> RM01 | C6: =CADASTRO_CASAS_BOMBA!$I$6*HORAS_CAPTACAO_DIA -> 10499.4 | D6: =MAX(BALANCO_DIARIO!$D$7:$D$468) -> 5163.0099 | E6: =COUNTIF(BALANCO_DIARIO!$F$7:$F$468,">0") -> 0 | F6: =IFERROR(INDEX(BALANCO_DIARIO!$B$7:$B$468,MATCH(1,INDEX(--(BALANCO_DIARIO!$F$7:$F$468>0),0),0)),"-") -> - | G6: =IFERROR(LOOKUP(2,1/(BALANCO_DIARIO!$F$7:$F$468>0),BALANCO_DIARIO!$B$7:$B$468),"-") -> - | H6: =SUM(BALANCO_DIARIO!$F$7:$F$468) -> 0 | I6: =MAX(BALANCO_DIARIO!$F$7:$F$468) -> 0 | J6: =IFERROR($I6/CADASTRO_CASAS_BOMBA!$I$6,0) -> 0 | K6: =IFERROR($I6/HORAS_CAPTACAO_DIA,0) -> 0 | L6: =IF($E6=0,"OK - captacao cobre o consumo",IF($E6<=7,"ATENCAO - falta pontual","CRITICO - falta recorrente")) -> OK - captacao cobre o consumo | M6: =IF($E6=0,"Sem acao: a captacao atende o consumo o ano todo.","Falta em "&$E6&" dia(s), pico de "&TEXT($I6,"#,##0")&" m3/dia (~"&TEXT($J6,"0.0")&" h extras de captacao ou +"&TEXT($K6,"#,##0")&" m3/h). Alternativas: escalonar plantio, reduzir simultaneidade, ampliar captacao ou priorizar os pivos criticos.") -> Sem acao: a captacao atende o consumo o ano todo.
B7: =CADASTRO_CASAS_BOMBA!$B$7 -> RM02 | C7: =CADASTRO_CASAS_BOMBA!$I$7*HORAS_CAPTACAO_DIA -> 10499.4 | D7: =MAX(BALANCO_DIARIO!$G$7:$G$468) -> 9867.6497 | E7: =COUNTIF(BALANCO_DIARIO!$I$7:$I$468,">0") -> 0 | F7: =IFERROR(INDEX(BALANCO_DIARIO!$B$7:$B$468,MATCH(1,INDEX(--(BALANCO_DIARIO!$I$7:$I$468>0),0),0)),"-") -> - | G7: =IFERROR(LOOKUP(2,1/(BALANCO_DIARIO!$I$7:$I$468>0),BALANCO_DIARIO!$B$7:$B$468),"-") -> - | H7: =SUM(BALANCO_DIARIO!$I$7:$I$468) -> 0 | I7: =MAX(BALANCO_DIARIO!$I$7:$I$468) -> 0 | J7: =IFERROR($I7/CADASTRO_CASAS_BOMBA!$I$7,0) -> 0 | K7: =IFERROR($I7/HORAS_CAPTACAO_DIA,0) -> 0 | L7: =IF($E7=0,"OK - captacao cobre o consumo",IF($E7<=7,"ATENCAO - falta pontual","CRITICO - falta recorrente")) -> OK - captacao cobre o consumo | M7: =IF($E7=0,"Sem acao: a captacao atende o consumo o ano todo.","Falta em "&$E7&" dia(s), pico de "&TEXT($I7,"#,##0")&" m3/dia (~"&TEXT($J7,"0.0")&" h extras de captacao ou +"&TEXT($K7,"#,##0")&" m3/h). Alternativas: escalonar plantio, reduzir simultaneidade, ampliar captacao ou priorizar os pivos criticos.") -> Sem acao: a captacao atende o consumo o ano todo.
B8: =CADASTRO_CASAS_BOMBA!$B$8 -> RM03 | C8: =CADASTRO_CASAS_BOMBA!$I$8*HORAS_CAPTACAO_DIA -> 10499.4 | D8: =MAX(BALANCO_DIARIO!$J$7:$J$468) -> 10470.36 | E8: =COUNTIF(BALANCO_DIARIO!$L$7:$L$468,">0") -> 0 | F8: =IFERROR(INDEX(BALANCO_DIARIO!$B$7:$B$468,MATCH(1,INDEX(--(BALANCO_DIARIO!$L$7:$L$468>0),0),0)),"-") -> - | G8: =IFERROR(LOOKUP(2,1/(BALANCO_DIARIO!$L$7:$L$468>0),BALANCO_DIARIO!$B$7:$B$468),"-") -> - | H8: =SUM(BALANCO_DIARIO!$L$7:$L$468) -> 0 | I8: =MAX(BALANCO_DIARIO!$L$7:$L$468) -> 0 | J8: =IFERROR($I8/CADASTRO_CASAS_BOMBA!$I$8,0) -> 0 | K8: =IFERROR($I8/HORAS_CAPTACAO_DIA,0) -> 0 | L8: =IF($E8=0,"OK - captacao cobre o consumo",IF($E8<=7,"ATENCAO - falta pontual","CRITICO - falta recorrente")) -> OK - captacao cobre o consumo | M8: =IF($E8=0,"Sem acao: a captacao atende o consumo o ano todo.","Falta em "&$E8&" dia(s), pico de "&TEXT($I8,"#,##0")&" m3/dia (~"&TEXT($J8,"0.0")&" h extras de captacao ou +"&TEXT($K8,"#,##0")&" m3/h). Alternativas: escalonar plantio, reduzir simultaneidade, ampliar captacao ou priorizar os pivos criticos.") -> Sem acao: a captacao atende o consumo o ano todo.
B9: =CADASTRO_CASAS_BOMBA!$B$9 -> RM04 | C9: =CADASTRO_CASAS_BOMBA!$I$9*HORAS_CAPTACAO_DIA -> 21630.6 | D9: =MAX(BALANCO_DIARIO!$M$7:$M$468) -> 26385.252 | E9: =COUNTIF(BALANCO_DIARIO!$O$7:$O$468,">0") -> 0 | F9: =IFERROR(INDEX(BALANCO_DIARIO!$B$7:$B$468,MATCH(1,INDEX(--(BALANCO_DIARIO!$O$7:$O$468>0),0),0)),"-") -> - | G9: =IFERROR(LOOKUP(2,1/(BALANCO_DIARIO!$O$7:$O$468>0),BALANCO_DIARIO!$B$7:$B$468),"-") -> - | H9: =SUM(BALANCO_DIARIO!$O$7:$O$468) -> 0 | I9: =MAX(BALANCO_DIARIO!$O$7:$O$468) -> 0 | J9: =IFERROR($I9/CADASTRO_CASAS_BOMBA!$I$9,0) -> 0 | K9: =IFERROR($I9/HORAS_CAPTACAO_DIA,0) -> 0 | L9: =IF($E9=0,"OK - captacao cobre o consumo",IF($E9<=7,"ATENCAO - falta pontual","CRITICO - falta recorrente")) -> OK - captacao cobre o consumo | M9: =IF($E9=0,"Sem acao: a captacao atende o consumo o ano todo.","Falta em "&$E9&" dia(s), pico de "&TEXT($I9,"#,##0")&" m3/dia (~"&TEXT($J9,"0.0")&" h extras de captacao ou +"&TEXT($K9,"#,##0")&" m3/h). Alternativas: escalonar plantio, reduzir simultaneidade, ampliar captacao ou priorizar os pivos criticos.") -> Sem acao: a captacao atende o consumo o ano todo.
B10: =CADASTRO_CASAS_BOMBA!$B$10 -> RM05 | C10: =CADASTRO_CASAS_BOMBA!$I$10*HORAS_CAPTACAO_DIA -> 13082.4 | D10: =MAX(BALANCO_DIARIO!$P$7:$P$468) -> 34521.125 | E10: =COUNTIF(BALANCO_DIARIO!$R$7:$R$468,">0") -> 32 | F10: =IFERROR(INDEX(BALANCO_DIARIO!$B$7:$B$468,MATCH(1,INDEX(--(BALANCO_DIARIO!$R$7:$R$468>0),0),0)),"-") -> 46639 | G10: =IFERROR(LOOKUP(2,1/(BALANCO_DIARIO!$R$7:$R$468>0),BALANCO_DIARIO!$B$7:$B$468),"-") -> 46670 | H10: =SUM(BALANCO_DIARIO!$R$7:$R$468) -> 455366.72 | I10: =MAX(BALANCO_DIARIO!$R$7:$R$468) -> 21438.725 | J10: =IFERROR($I10/CADASTRO_CASAS_BOMBA!$I$10,0) -> 29.49742 | K10: =IFERROR($I10/HORAS_CAPTACAO_DIA,0) -> 1191.0403 | L10: =IF($E10=0,"OK - captacao cobre o consumo",IF($E10<=7,"ATENCAO - falta pontual","CRITICO - falta recorrente")) -> CRITICO - falta recorrente | M10: =IF($E10=0,"Sem acao: a captacao atende o consumo o ano todo.","Falta em "&$E10&" dia(s), pico de "&TEXT($I10,"#,##0")&" m3/dia (~"&TEXT($J10,"0.0")&" h extras de captacao ou +"&TEXT($K10,"#,##0")&" m3/h). Alternativas: escalonar plantio, reduzir simultaneidade, ampliar captacao ou priorizar os pivos criticos.") -> Falta em 32 dia(s), pico de 21,439 m3/dia (~29.5 h extras de captacao ou +1,191 m3/h). Alternativas: escalonar plantio, reduzir simultaneidade, ampliar captacao ou priorizar os pivos criticos.
B11: =CADASTRO_CASAS_BOMBA!$B$11 -> RM06 | C11: =CADASTRO_CASAS_BOMBA!$I$11*HORAS_CAPTACAO_DIA -> 21420 | D11: =MAX(BALANCO_DIARIO!$S$7:$S$468) -> 39230.524 | E11: =COUNTIF(BALANCO_DIARIO!$U$7:$U$468,">0") -> 68 | F11: =IFERROR(INDEX(BALANCO_DIARIO!$B$7:$B$468,MATCH(1,INDEX(--(BALANCO_DIARIO!$U$7:$U$468>0),0),0)),"-") -> 46516 | G11: =IFERROR(LOOKUP(2,1/(BALANCO_DIARIO!$U$7:$U$468>0),BALANCO_DIARIO!$B$7:$B$468),"-") -> 46663 | H11: =SUM(BALANCO_DIARIO!$U$7:$U$468) -> 626266.6 | I11: =MAX(BALANCO_DIARIO!$U$7:$U$468) -> 17054.301 | J11: =IFERROR($I11/CADASTRO_CASAS_BOMBA!$I$11,0) -> 14.331345 | K11: =IFERROR($I11/HORAS_CAPTACAO_DIA,0) -> 947.46116 | L11: =IF($E11=0,"OK - captacao cobre o consumo",IF($E11<=7,"ATENCAO - falta pontual","CRITICO - falta recorrente")) -> CRITICO - falta recorrente | M11: =IF($E11=0,"Sem acao: a captacao atende o consumo o ano todo.","Falta em "&$E11&" dia(s), pico de "&TEXT($I11,"#,##0")&" m3/dia (~"&TEXT($J11,"0.0")&" h extras de captacao ou +"&TEXT($K11,"#,##0")&" m3/h). Alternativas: escalonar plantio, reduzir simultaneidade, ampliar captacao ou priorizar os pivos criticos.") -> Falta em 68 dia(s), pico de 17,054 m3/dia (~14.3 h extras de captacao ou +947 m3/h). Alternativas: escalonar plantio, reduzir simultaneidade, ampliar captacao ou priorizar os pivos criticos.
B12: =CADASTRO_CASAS_BOMBA!$B$12 -> RM07 | C12: =CADASTRO_CASAS_BOMBA!$I$12*HORAS_CAPTACAO_DIA -> 25380 | D12: =MAX(BALANCO_DIARIO!$V$7:$V$468) -> 58274.495 | E12: =COUNTIF(BALANCO_DIARIO!$X$7:$X$468,">0") -> 113 | F12: =IFERROR(INDEX(BALANCO_DIARIO!$B$7:$B$468,MATCH(1,INDEX(--(BALANCO_DIARIO!$X$7:$X$468>0),0),0)),"-") -> 46511 | G12: =IFERROR(LOOKUP(2,1/(BALANCO_DIARIO!$X$7:$X$468>0),BALANCO_DIARIO!$B$7:$B$468),"-") -> 46656 | H12: =SUM(BALANCO_DIARIO!$X$7:$X$468) -> 1831393.4 | I12: =MAX(BALANCO_DIARIO!$X$7:$X$468) -> 32894.495 | J12: =IFERROR($I12/CADASTRO_CASAS_BOMBA!$I$12,0) -> 23.329429 | K12: =IFERROR($I12/HORAS_CAPTACAO_DIA,0) -> 1827.472 | L12: =IF($E12=0,"OK - captacao cobre o consumo",IF($E12<=7,"ATENCAO - falta pontual","CRITICO - falta recorrente")) -> CRITICO - falta recorrente | M12: =IF($E12=0,"Sem acao: a captacao atende o consumo o ano todo.","Falta em "&$E12&" dia(s), pico de "&TEXT($I12,"#,##0")&" m3/dia (~"&TEXT($J12,"0.0")&" h extras de captacao ou +"&TEXT($K12,"#,##0")&" m3/h). Alternativas: escalonar plantio, reduzir simultaneidade, ampliar captacao ou priorizar os pivos criticos.") -> Falta em 113 dia(s), pico de 32,894 m3/dia (~23.3 h extras de captacao ou +1,827 m3/h). Alternativas: escalonar plantio, reduzir simultaneidade, ampliar captacao ou priorizar os pivos criticos.
B13: =CADASTRO_CASAS_BOMBA!$B$13 -> RM08 | C13: =CADASTRO_CASAS_BOMBA!$I$13*HORAS_CAPTACAO_DIA -> 0 | D13: =MAX(BALANCO_DIARIO!$Y$7:$Y$468) -> 0 | E13: =COUNTIF(BALANCO_DIARIO!$AA$7:$AA$468,">0") -> 0 | F13: =IFERROR(INDEX(BALANCO_DIARIO!$B$7:$B$468,MATCH(1,INDEX(--(BALANCO_DIARIO!$AA$7:$AA$468>0),0),0)),"-") -> - | G13: =IFERROR(LOOKUP(2,1/(BALANCO_DIARIO!$AA$7:$AA$468>0),BALANCO_DIARIO!$B$7:$B$468),"-") -> - | H13: =SUM(BALANCO_DIARIO!$AA$7:$AA$468) -> 0 | I13: =MAX(BALANCO_DIARIO!$AA$7:$AA$468) -> 0 | J13: =IFERROR($I13/CADASTRO_CASAS_BOMBA!$I$13,0) -> 0 | K13: =IFERROR($I13/HORAS_CAPTACAO_DIA,0) -> 0 | L13: =IF($E13=0,"OK - captacao cobre o consumo",IF($E13<=7,"ATENCAO - falta pontual","CRITICO - falta recorrente")) -> OK - captacao cobre o consumo | M13: =IF($E13=0,"Sem acao: a captacao atende o consumo o ano todo.","Falta em "&$E13&" dia(s), pico de "&TEXT($I13,"#,##0")&" m3/dia (~"&TEXT($J13,"0.0")&" h extras de captacao ou +"&TEXT($K13,"#,##0")&" m3/h). Alternativas: escalonar plantio, reduzir simultaneidade, ampliar captacao ou priorizar os pivos criticos.") -> Sem acao: a captacao atende o consumo o ano todo.
B15: RESUMO DA RDM
B16: Casas com falta de agua | F16: =COUNTIF($E$6:$E$13,">0") -> 3
B17: Total de dias-casa com falta | F17: =SUM($E$6:$E$13) -> 213
B18: Volume total faltante na safra (m3) | F18: =SUM($H$6:$H$13) -> 2913026.7
B19: Casa mais critica | F19: =IFERROR(INDEX($B$6:$B$13,MATCH(MAX($E$6:$E$13),$E$6:$E$13,0)),"-") -> RM07
B21: Como usar: se uma casa aparece CRITICO, teste mover a data de plantio dos pivos dela (ROTACAO_RDM) para afastar o pico, ou ajuste as horas de captacao (PARAMETROS_GERAIS). Tudo se refaz na hora.

Sheet CAPACIDADE_21H
B2: CAPACIDADE_21H - a infraestrutura cabe em 21 horas por dia?
B3: Uma linha por semana. Demanda x capacidade em HORAS_OPERACAO_DIA x DIAS_POR_SEMANA, nos quatro niveis: pivo, casa de bomba, trecho de canal e sistema RDM.
B5: Semana | C5: Data inicial | D5: Data final | E5: Volume necessario (m3) | F5: Capacidade maxima da semana (m3) | G5: Utilizacao do sistema (%) | H5: Deficit de volume (m3) | I5: Deficit de vazao (m3/h) | J5: Deficit de horas (h) | K5: Horas adicionais necessarias (h) | L5: Vazao adicional necessaria (m3/h) | M5: Status do sistema | N5: Utilizacao max. de pivo (%) | O5: Pivo mais critico | P5: Status do pivo | Q5: Utilizacao da casa mais critica (%) | R5: Casa mais critica | S5: Status da casa | T5: Utilizacao do trecho mais critico (%) | U5: Trecho mais critico | V5: Status do trecho | W5: Chave de ordenacao
B6: =SEMANAS!$B$6 -> 1 | C6: =SEMANAS!$C$6 -> 46265 | D6: =SEMANAS!$D$6 -> 46271 | E6: =AUX_MATRIZES!C140 -> 486377.64 | F6: =AUX_MATRIZES!C156*SEMANAS!$K$6 -> 4470818.1 | G6: =IFERROR($E6/$F6,0) -> 0.1087894 | H6: =MAX(0,$E6-$F6) -> 0 | I6: =AUX_MATRIZES!C158 -> 0 | J6: =AUX_MATRIZES!C160 -> 0 | K6: =IFERROR(MAX(0,$E6/AUX_MATRIZES!C156-SEMANAS!$K$6),0) -> 0 | L6: =IFERROR(MAX(0,$E6/SEMANAS!$K$6-AUX_MATRIZES!C156),0) -> 0 | M6: =IF($G6>LIMITE_CRITICO,"INVIAVEL - demanda excede a capacidade em 21 h/dia",IF($G6>LIMITE_ATENCAO,"CRITICO - utilizacao acima de "&TEXT(LIMITE_ATENCAO,"0%"),IF($G6>LIMITE_CONFORTAVEL,"ATENCAO - utilizacao acima de "&TEXT(LIMITE_CONFORTAVEL,"0%"),"OK - capacidade suficiente"))) -> OK - capacidade suficiente | N6: =AUX_MATRIZES!C148 -> 0.46019048 | O6: =AUX_MATRIZES!C149 -> PV 131 | P6: =IF($N6>LIMITE_CRITICO,"INVIAVEL - demanda excede a capacidade em 21 h/dia",IF($N6>LIMITE_ATENCAO,"CRITICO - utilizacao acima de "&TEXT(LIMITE_ATENCAO,"0%"),IF($N6>LIMITE_CONFORTAVEL,"ATENCAO - utilizacao acima de "&TEXT(LIMITE_CONFORTAVEL,"0%"),"OK - capacidade suficiente"))) -> OK - capacidade suficiente | Q6: =AUX_MATRIZES!C150 -> 0.14789097 | R6: =AUX_MATRIZES!C151 -> RM06 | S6: =IF($Q6>LIMITE_CRITICO,"INVIAVEL - demanda excede a capacidade em 21 h/dia",IF($Q6>LIMITE_ATENCAO,"CRITICO - utilizacao acima de "&TEXT(LIMITE_ATENCAO,"0%"),IF($Q6>LIMITE_CONFORTAVEL,"ATENCAO - utilizacao acima de "&TEXT(LIMITE_CONFORTAVEL,"0%"),"OK - capacidade suficiente"))) -> OK - capacidade suficiente | T6: =AUX_MATRIZES!C152 -> 0.14789097 | U6: =AUX_MATRIZES!C153 -> TR06 | V6: =IF($T6>LIMITE_CRITICO,"INVIAVEL - demanda excede a capacidade em 21 h/dia",IF($T6>LIMITE_ATENCAO,"CRITICO - utilizacao acima de "&TEXT(LIMITE_ATENCAO,"0%"),IF($T6>LIMITE_CONFORTAVEL,"ATENCAO - utilizacao acima de "&TEXT(LIMITE_CONFORTAVEL,"0%"),"OK - capacidade suficiente"))) -> OK - capacidade suficiente | W6: =AUX_MATRIZES!C161 -> 486377.64
B7: =SEMANAS!$B$7 -> 2 | C7: =SEMANAS!$C$7 -> 46272 | D7: =SEMANAS!$D$7 -> 46278 | E7: =AUX_MATRIZES!D140 -> 404088.51 | F7: =AUX_MATRIZES!D156*SEMANAS!$K$7 -> 4470818.1 | G7: =IFERROR($E7/$F7,0) -> 0.090383572 | H7: =MAX(0,$E7-$F7) -> 0 | I7: =AUX_MATRIZES!D158 -> 0 | J7: =AUX_MATRIZES!D160 -> 0 | K7: =IFERROR(MAX(0,$E7/AUX_MATRIZES!D156-SEMANAS!$K$7),0) -> 0 | L7: =IFERROR(MAX(0,$E7/SEMANAS!$K$7-AUX_MATRIZES!D156),0) -> 0 | M7: =IF($G7>LIMITE_CRITICO,"INVIAVEL - demanda excede a capacidade em 21 h/dia",IF($G7>LIMITE_ATENCAO,"CRITICO - utilizacao acima de "&TEXT(LIMITE_ATENCAO,"0%"),IF($G7>LIMITE_CONFORTAVEL,"ATENCAO - utilizacao acima de "&TEXT(LIMITE_CONFORTAVEL,"0%"),"OK - capacidade suficiente"))) -> OK - capacidade suficiente | N7: =AUX_MATRIZES!D148 -> 0.46039216 | O7: =AUX_MATRIZES!D149 -> PV 102 | P7: =IF($N7>LIMITE_CRITICO,"INVIAVEL - demanda excede a capacidade em 21 h/dia",IF($N7>LIMITE_ATENCAO,"CRITICO - utilizacao acima de "&TEXT(LIMITE_ATENCAO,"0%"),IF($N7>LIMITE_CONFORTAVEL,"ATENCAO - utilizacao acima de "&TEXT(LIMITE_CONFORTAVEL,"0%"),"OK - capacidade suficiente"))) -> OK - capacidade suficiente | Q7: =AUX_MATRIZES!D150 -> 0.12611709 | R7: =AUX_MATRIZES!D151 -> RM05 | S7: =IF($Q7>LIMITE_CRITICO,"INVIAVEL - demanda excede a capacidade em 21 h/dia",IF($Q7>LIMITE_ATENCAO,"CRITICO - utilizacao acima de "&TEXT(LIMITE_ATENCAO,"0%"),IF($Q7>LIMITE_CONFORTAVEL,"ATENCAO - utilizacao acima de "&TEXT(LIMITE_CONFORTAVEL,"0%"),"OK - capacidade suficiente"))) -> OK - capacidade suficiente | T7: =AUX_MATRIZES!D152 -> 0.12611709 | U7: =AUX_MATRIZES!D153 -> TR05 | V7: =IF($T7>LIMITE_CRITICO,"INVIAVEL - demanda excede a capacidade em 21 h/dia",IF($T7>LIMITE_ATENCAO,"CRITICO - utilizacao acima de "&TEXT(LIMITE_ATENCAO,"0%"),IF($T7>LIMITE_CONFORTAVEL,"ATENCAO - utilizacao acima de "&TEXT(LIMITE_CONFORTAVEL,"0%"),"OK - capacidade suficiente"))) -> OK - capacidade suficiente | W7: =AUX_MATRIZES!D161 -> 404088.51
B8: =SEMANAS!$B$8 -> 3 | C8: =SEMANAS!$C$8 -> 46279 | D8: =SEMANAS!$D$8 -> 46285 | E8: =AUX_MATRIZES!E140 -> 318745.84 | F8: =AUX_MATRIZES!E156*SEMANAS!$K$8 -> 4470818.1 | G8: =IFERROR($E8/$F8,0) -> 0.071294745 | H8: =MAX(0,$E8-$F8) -> 0 | I8: =AUX_MATRIZES!E158 -> 0 | J8: =AUX_MATRIZES!E160 -> 0 | K8: =IFERROR(MAX(0,$E8/AUX_MATRIZES!E156-SEMANAS!$K$8),0) -> 0 | L8: =IFERROR(MAX(0,$E8/SEMANAS!$K$8-AUX_MATRIZES!E156),0) -> 0 | M8: =IF($G8>LIMITE_CRITICO,"INVIAVEL - demanda excede a capacidade em 21 h/dia",IF($G8>LIMITE_ATENCAO,"CRITICO - utilizacao acima de "&TEXT(LIMITE_ATENCAO,"0%"),IF($G8>LIMITE_CONFORTAVEL,"ATENCAO - utilizacao acima de "&TEXT(LIMITE_CONFORTAVEL,"0%"),"OK - capacidade suficiente"))) -> OK - capacidade suficiente | N8: =AUX_MATRIZES!E148 -> 0.46039216 | O8: =AUX_MATRIZES!E149 -> PV 102 | P8: =IF($N8>LIMITE_CRITICO,"INVIAVEL - demanda excede a capacidade em 21 h/dia",IF($N8>LIMITE_ATENCAO,"CRITICO - utilizacao acima de "&TEXT(LIMITE_ATENCAO,"0%"),IF($N8>LIMITE_CONFORTAVEL,"ATENCAO - utilizacao acima de "&TEXT(LIMITE_CONFORTAVEL,"0%"),"OK - capacidade suficiente"))) -> OK - capacidade suficiente | Q8: =AUX_MATRIZES!E150 -> 0.12611709 | R8: =AUX_MATRIZES!E151 -> RM05 | S8: =IF($Q8>LIMITE_CRITICO,"INVIAVEL - demanda excede a capacidade em 21 h/dia",IF($Q8>LIMITE_ATENCAO,"CRITICO - utilizacao acima de "&TEXT(LIMITE_ATENCAO,"0%"),IF($Q8>LIMITE_CONFORTAVEL,"ATENCAO - utilizacao acima de "&TEXT(LIMITE_CONFORTAVEL,"0%"),"OK - capacidade suficiente"))) -> OK - capacidade suficiente | T8: =AUX_MATRIZES!E152 -> 0.12611709 | U8: =AUX_MATRIZES!E153 -> TR05 | V8: =IF($T8>LIMITE_CRITICO,"INVIAVEL - demanda excede a capacidade em 21 h/dia",IF($T8>LIMITE_ATENCAO,"CRITICO - utilizacao acima de "&TEXT(LIMITE_ATENCAO,"0%"),IF($T8>LIMITE_CONFORTAVEL,"ATENCAO - utilizacao acima de "&TEXT(LIMITE_CONFORTAVEL,"0%"),"OK - capacidade suficiente"))) -> OK - capacidade suficiente | W8: =AUX_MATRIZES!E161 -> 318745.84
B9: =SEMANAS!$B$9 -> 4 | C9: =SEMANAS!$C$9 -> 46286 | D9: =SEMANAS!$D$9 -> 46292 | E9: =AUX_MATRIZES!F140 -> 270863.02 | F9: =AUX_MATRIZES!F156*SEMANAS!$K$9 -> 4470818.1 | G9: =IFERROR($E9/$F9,0) -> 0.060584666 | H9: =MAX(0,$E9-$F9) -> 0 | I9: =AUX_MATRIZES!F158 -> 0 | J9: =AUX_MATRIZES!F160 -> 0 | K9: =IFERROR(MAX(0,$E9/AUX_MATRIZES!F156-SEMANAS!$K$9),0) -> 0 | L9: =IFERROR(MAX(0,$E9/SEMANAS!$K$9-AUX_MATRIZES!F156),0) -> 0 | M9: =IF($G9>LIMITE_CRITICO,"INVIAVEL - demanda excede a capacidade em 21 h/dia",IF($G9>LIMITE_ATENCAO,"CRITICO - utilizacao acima de "&TEXT(LIMITE_ATENCAO,"0%"),IF($G9>LIMITE_CONFORTAVEL,"ATENCAO - utilizacao acima de "&TEXT(LIMITE_CONFORTAVEL,"0%"),"OK - capacidade suficiente"))) -> OK - capacidade suficiente | N9: =AUX_MATRIZES!F148 -> 0.46039216 | O9: =AUX_MATRIZES!F149 -> PV 102 | P9: =IF($N9>LIMITE_CRITICO,"INVIAVEL - demanda excede a capacidade em 21 h/dia",IF($N9>LIMITE_ATENCAO,"CRITICO - utilizacao acima de "&TEXT(LIMITE_ATENCAO,"0%"),IF($N9>LIMITE_CONFORTAVEL,"ATENCAO - utilizacao acima de "&TEXT(LIMITE_CONFORTAVEL,"0%"),"OK - capacidade suficiente"))) -> OK - capacidade suficiente | Q9: =AUX_MATRIZES!F150 -> 0.12611709 | R9: =AUX_MATRIZES!F151 -> RM05 | S9: =IF($Q9>LIMITE_CRITICO,"INVIAVEL - demanda excede a capacidade em 21 h/dia",IF($Q9>LIMITE_ATENCAO,"CRITICO - utilizacao acima de "&TEXT(LIMITE_ATENCAO,"0%"),IF($Q9>LIMITE_CONFORTAVEL,"ATENCAO - utilizacao acima de "&TEXT(LIMITE_CONFORTAVEL,"0%"),"OK - capacidade suficiente"))) -> OK - capacidade suficiente | T9: =AUX_MATRIZES!F152 -> 0.12611709 | U9: =AUX_MATRIZES!F153 -> TR05 | V9: =IF($T9>LIMITE_CRITICO,"INVIAVEL - demanda excede a capacidade em 21 h/dia",IF($T9>LIMITE_ATENCAO,"CRITICO - utilizacao acima de "&TEXT(LIMITE_ATENCAO,"0%"),IF($T9>LIMITE_CONFORTAVEL,"ATENCAO - utilizacao acima de "&TEXT(LIMITE_CONFORTAVEL,"0%"),"OK - capacidade suficiente"))) -> OK - capacidade suficiente | W9: =AUX_MATRIZES!F161 -> 270863.02
B10: =SEMANAS!$B$10 -> 5 | C10: =SEMANAS!$C$10 -> 46293 | D10: =SEMANAS!$D$10 -> 46299 | E10: =AUX_MATRIZES!G140 -> 186962.27 | F10: =AUX_MATRIZES!G156*SEMANAS!$K$10 -> 4470818.1 | G10: =IFERROR($E10/$F10,0) -> 0.041818357 | H10: =MAX(0,$E10-$F10) -> 0 | I10: =AUX_MATRIZES!G158 -> 0 | J10: =AUX_MATRIZES!G160 -> 0 | K10: =IFERROR(MAX(0,$E10/AUX_MATRIZES!G156-SEMANAS!$K$10),0) -> 0 | L10: =IFERROR(MAX(0,$E10/SEMANAS!$K$10-AUX_MATRIZES!G156),0) -> 0 | M10: =IF($G10>LIMITE_CRITICO,"INVIAVEL - demanda excede a capacidade em 21 h/dia",IF($G10>LIMITE_ATENCAO,"CRITICO - utilizacao acima de "&TEXT(LIMITE_ATENCAO,"0%"),IF($G10>LIMITE_CONFORTAVEL,"ATENCAO - utilizacao acima de "&TEXT(LIMITE_CONFORTAVEL,"0%"),"OK - capacidade suficiente"))) -> OK - capacidade suficiente | N10: =AUX_MATRIZES!G148 -> 0.34718207 | O10: =AUX_MATRIZES!G149 -> PV 102 | P10: =IF($N10>LIMITE_CRITICO,"INVIAVEL - demanda excede a capacidade em 21 h/dia",IF($N10>LIMITE_ATENCAO,"CRITICO - utilizacao acima de "&TEXT(LIMITE_ATENCAO,"0%"),IF($N10>LIMITE_CONFORTAVEL,"ATENCAO - utilizacao acima de "&TEXT(LIMITE_CONFORTAVEL,"0%"),"OK - capacidade suficiente"))) -> OK - capacidade suficiente | Q10: =AUX_MATRIZES!G150 -> 0.095104995 | R10: =AUX_MATRIZES!G151 -> RM05 | S10: =IF($Q10>LIMITE_CRITICO,"INVIAVEL - demanda excede a capacidade em 21 h/dia",IF($Q10>LIMITE_ATENCAO,"CRITICO - utilizacao acima de "&TEXT(LIMITE_ATENCAO,"0%"),IF($Q10>LIMITE_CONFORTAVEL,"ATENCAO - utilizacao acima de "&TEXT(LIMITE_CONFORTAVEL,"0%"),"OK - capacidade suficiente"))) -> OK - capacidade suficiente | T10: =AUX_MATRIZES!G152 -> 0.095104995 | U10: =AUX_MATRIZES!G153 -> TR05 | V10: =IF($T10>LIMITE_CRITICO,"INVIAVEL - demanda excede a capacidade em 21 h/dia",IF($T10>LIMITE_ATENCAO,"CRITICO - utilizacao acima de "&TEXT(LIMITE_ATENCAO,"0%"),IF($T10>LIMITE_CONFORTAVEL,"ATENCAO - utilizacao acima de "&TEXT(LIMITE_CONFORTAVEL,"0%"),"OK - capacidade suficiente"))) -> OK - capacidade suficiente | W10: =AUX_MATRIZES!G161 -> 186962.27
B11: =SEMANAS!$B$11 -> 6 | C11: =SEMANAS!$C$11 -> 46300 | D11: =SEMANAS!$D$11 -> 46306 | E11: =AUX_MATRIZES!H140 -> 105840.3 | F11: =AUX_MATRIZES!H156*SEMANAS!$K$11 -> 4470818.1 | G11: =IFERROR($E11/$F11,0) -> 0.023673588 | H11: =MAX(0,$E11-$F11) -> 0 | I11: =AUX_MATRIZES!H158 -> 0 | J11: =AUX_MATRIZES!H160 -> 0 | K11: =IFERROR(MAX(0,$E11/AUX_MATRIZES!H156-SEMANAS!$K$11),0) -> 0 | L11: =IFERROR(MAX(0,$E11/SEMANAS!$K$11-AUX_MATRIZES!H156),0) -> 0 | M11: =IF($G11>LIMITE_CRITICO,"INVIAVEL - demanda excede a capacidade em 21 h/dia",IF($G11>LIMITE_ATENCAO,"CRITICO - utilizacao acima de "&TEXT(LIMITE_ATENCAO,"0%"),IF($G11>LIMITE_CONFORTAVEL,"ATENCAO - utilizacao acima de "&TEXT(LIMITE_CONFORTAVEL,"0%"),"OK - capacidade suficiente"))) -> OK - capacidade suficiente | N11: =AUX_MATRIZES!H148 -> 0.26227451 | O11: =AUX_MATRIZES!H149 -> PV 102 | P11: =IF($N11>LIMITE_CRITICO,"INVIAVEL - demanda excede a capacidade em 21 h/dia",IF($N11>LIMITE_ATENCAO,"CRITICO - utilizacao acima de "&TEXT(LIMITE_ATENCAO,"0%"),IF($N11>LIMITE_CONFORTAVEL,"ATENCAO - utilizacao acima de "&TEXT(LIMITE_CONFORTAVEL,"0%"),"OK - capacidade suficiente"))) -> OK - capacidade suficiente | Q11: =AUX_MATRIZES!H150 -> 0.071845922 | R11: =AUX_MATRIZES!H151 -> RM05 | S11: =IF($Q11>LIMITE_CRITICO,"INVIAVEL - demanda excede a capacidade em 21 h/dia",IF($Q11>LIMITE_ATENCAO,"CRITICO - utilizacao acima de "&TEXT(LIMITE_ATENCAO,"0%"),IF($Q11>LIMITE_CONFORTAVEL,"ATENCAO - utilizacao acima de "&TEXT(LIMITE_CONFORTAVEL,"0%"),"OK - capacidade suficiente"))) -> OK - capacidade suficiente | T11: =AUX_MATRIZES!H152 -> 0.071845922 | U11: =AUX_MATRIZES!H153 -> TR05 | V11: =IF($T11>LIMITE_CRITICO,"INVIAVEL - demanda excede a capacidade em 21 h/dia",IF($T11>LIMITE_ATENCAO,"CRITICO - utilizacao acima de "&TEXT(LIMITE_ATENCAO,"0%"),IF($T11>LIMITE_CONFORTAVEL,"ATENCAO - utilizacao acima de "&TEXT(LIMITE_CONFORTAVEL,"0%"),"OK - capacidade suficiente"))) -> OK - capacidade suficiente | W11: =AUX_MATRIZES!H161 -> 105840.3
B12: =SEMANAS!$B$12 -> 7 | C12: =SEMANAS!$C$12 -> 46307 | D12: =SEMANAS!$D$12 -> 46313 | E12: =AUX_MATRIZES!I140 -> 99184.733 | F12: =AUX_MATRIZES!I156*SEMANAS!$K$12 -> 4470818.1 | G12: =IFERROR($E12/$F12,0) -> 0.022184918 | H12: =MAX(0,$E12-$F12) -> 0 | I12: =AUX_MATRIZES!I158 -> 0 | J12: =AUX_MATRIZES!I160 -> 0 | K12: =IFERROR(MAX(0,$E12/AUX_MATRIZES!I156-SEMANAS!$K$12),0) -> 0 | L12: =IFERROR(MAX(0,$E12/SEMANAS!$K$12-AUX_MATRIZES!I156),0) -> 0 | M12: =IF($G12>LIMITE_CRITICO,"INVIAVEL - demanda excede a capacidade em 21 h/dia",IF($G12>LIMITE_ATENCAO,"CRITICO - utilizacao acima de "&TEXT(LIMITE_ATENCAO,"0%"),IF($G12>LIMITE_CONFORTAVEL,"ATENCAO - utilizacao acima de "&TEXT(LIMITE_CONFORTAVEL,"0%"),"OK - capacidade suficiente"))) -> OK - capacidade suficiente | N12: =AUX_MATRIZES!I148 -> 0.26227451 | O12: =AUX_MATRIZES!I149 -> PV 102 | P12: =IF($N12>LIMITE_CRITICO,"INVIAVEL - demanda excede a capacidade em 21 h/dia",IF($N12>LIMITE_ATENCAO,"CRITICO - utilizacao acima de "&TEXT(LIMITE_ATENCAO,"0%"),IF($N12>LIMITE_CONFORTAVEL,"ATENCAO - utilizacao acima de "&TEXT(LIMITE_CONFORTAVEL,"0%"),"OK - capacidade suficiente"))) -> OK - capacidade suficiente | Q12: =AUX_MATRIZES!I150 -> 0.071845922 | R12: =AUX_MATRIZES!I151 -> RM05 | S12: =IF($Q12>LIMITE_CRITICO,"INVIAVEL - demanda excede a capacidade em 21 h/dia",IF($Q12>LIMITE_ATENCAO,"CRITICO - utilizacao acima de "&TEXT(LIMITE_ATENCAO,"0%"),IF($Q12>LIMITE_CONFORTAVEL,"ATENCAO - utilizacao acima de "&TEXT(LIMITE_CONFORTAVEL,"0%"),"OK - capacidade suficiente"))) -> OK - capacidade suficiente | T12: =AUX_MATRIZES!I152 -> 0.071845922 | U12: =AUX_MATRIZES!I153 -> TR05 | V12: =IF($T12>LIMITE_CRITICO,"INVIAVEL - demanda excede a capacidade em 21 h/dia",IF($T12>LIMITE_ATENCAO,"CRITICO - utilizacao acima de "&TEXT(LIMITE_ATENCAO,"0%"),IF($T12>LIMITE_CONFORTAVEL,"ATENCAO - utilizacao acima de "&TEXT(LIMITE_CONFORTAVEL,"0%"),"OK - capacidade suficiente"))) -> OK - capacidade suficiente | W12: =AUX_MATRIZES!I161 -> 99184.733
B13: =SEMANAS!$B$13 -> 8 | C13: =SEMANAS!$C$13 -> 46314 | D13: =SEMANAS!$D$13 -> 46320 | E13: =AUX_MATRIZES!J140 -> 97606.549 | F13: =AUX_MATRIZES!J156*SEMANAS!$K$13 -> 4470818.1 | G13: =IFERROR($E13/$F13,0) -> 0.021831921 | H13: =MAX(0,$E13-$F13) -> 0 | I13: =AUX_MATRIZES!J158 -> 0 | J13: =AUX_MATRIZES!J160 -> 0 | K13: =IFERROR(MAX(0,$E13/AUX_MATRIZES!J156-SEMANAS!$K$13),0) -> 0 | L13: =IFERROR(MAX(0,$E13/SEMANAS!$K$13-AUX_MATRIZES!J156),0) -> 0 | M13: =IF($G13>LIMITE_CRITICO,"INVIAVEL - demanda excede a capacidade em 21 h/dia",IF($G13>LIMITE_ATENCAO,"CRITICO - utilizacao acima de "&TEXT(LIMITE_ATENCAO,"0%"),IF($G13>LIMITE_CONFORTAVEL,"ATENCAO - utilizacao acima de "&TEXT(LIMITE_CONFORTAVEL,"0%"),"OK - capacidade suficiente"))) -> OK - capacidade suficiente | N13: =AUX_MATRIZES!J148 -> 0.26227451 | O13: =AUX_MATRIZES!J149 -> PV 102 | P13: =IF($N13>LIMITE_CRITICO,"INVIAVEL - demanda excede a capacidade em 21 h/dia",IF($N13>LIMITE_ATENCAO,"CRITICO - utilizacao acima de "&TEXT(LIMITE_ATENCAO,"0%"),IF($N13>LIMITE_CONFORTAVEL,"ATENCAO - utilizacao acima de "&TEXT(LIMITE_CONFORTAVEL,"0%"),"OK - capacidade suficiente"))) -> OK - capacidade suficiente | Q13: =AUX_MATRIZES!J150 -> 0.06191984 | R13: =AUX_MATRIZES!J151 -> RM05 | S13: =IF($Q13>LIMITE_CRITICO,"INVIAVEL - demanda excede a capacidade em 21 h/dia",IF($Q13>LIMITE_ATENCAO,"CRITICO - utilizacao acima de "&TEXT(LIMITE_ATENCAO,"0%"),IF($Q13>LIMITE_CONFORTAVEL,"ATENCAO - utilizacao acima de "&TEXT(LIMITE_CONFORTAVEL,"0%"),"OK - capacidade suficiente"))) -> OK - capacidade suficiente | T13: =AUX_MATRIZES!J152 -> 0.06191984 | U13: =AUX_MATRIZES!J153 -> TR05 | V13: =IF($T13>LIMITE_CRITICO,"INVIAVEL - demanda excede a capacidade em 21 h/dia",IF($T13>LIMITE_ATENCAO,"CRITICO - utilizacao acima de "&TEXT(LIMITE_ATENCAO,"0%"),IF($T13>LIMITE_CONFORTAVEL,"ATENCAO - utilizacao acima de "&TEXT(LIMITE_CONFORTAVEL,"0%"),"OK - capacidade suficiente"))) -> OK - capacidade suficiente | W13: =AUX_MATRIZES!J161 -> 97606.549
B14: =SEMANAS!$B$14 -> 9 | C14: =SEMANAS!$C$14 -> 46321 | D14: =SEMANAS!$D$14 -> 46327 | E14: =AUX_MATRIZES!K140 -> 101846.33 | F14: =AUX_MATRIZES!K156*SEMANAS!$K$14 -> 4470818.1 | G14: =IFERROR($E14/$F14,0) -> 0.022780245 | H14: =MAX(0,$E14-$F14) -> 0 | I14: =AUX_MATRIZES!K158 -> 0 | J14: =AUX_MATRIZES!K160 -> 0 | K14: =IFERROR(MAX(0,$E14/AUX_MATRIZES!K156-SEMANAS!$K$14),0) -> 0 | L14: =IFERROR(MAX(0,$E14/SEMANAS!$K$14-AUX_MATRIZES!K156),0) -> 0 | M14: =IF($G14>LIMITE_CRITICO,"INVIAVEL - demanda excede a capacidade em 21 h/dia",IF($G14>LIMITE_ATENCAO,"CRITICO - utilizacao acima de "&TEXT(LIMITE_ATENCAO,"0%"),IF($G14>LIMITE_CONFORTAVEL,"ATENCAO - utilizacao acima de "&TEXT(LIMITE_CONFORTAVEL,"0%"),"OK - capacidade suficiente"))) -> OK - capacidade suficiente | N14: =AUX_MATRIZES!K148 -> 0.20443137 | O14: =AUX_MATRIZES!K149 -> PV 102 | P14: =IF($N14>LIMITE_CRITICO,"INVIAVEL - demanda excede a capacidade em 21 h/dia",IF($N14>LIMITE_ATENCAO,"CRITICO - utilizacao acima de "&TEXT(LIMITE_ATENCAO,"0%"),IF($N14>LIMITE_CONFORTAVEL,"ATENCAO - utilizacao acima de "&TEXT(LIMITE_CONFORTAVEL,"0%"),"OK - capacidade suficiente"))) -> OK - capacidade suficiente | Q14: =AUX_MATRIZES!K150 -> 0.086363108 | R14: =AUX_MATRIZES!K151 -> RM01 | S14: =IF($Q14>LIMITE_CRITICO,"INVIAVEL - demanda excede a capacidade em 21 h/dia",IF($Q14>LIMITE_ATENCAO,"CRITICO - utilizacao acima de "&TEXT(LIMITE_ATENCAO,"0%"),IF($Q14>LIMITE_CONFORTAVEL,"ATENCAO - utilizacao acima de "&TEXT(LIMITE_CONFORTAVEL,"0%"),"OK - capacidade suficiente"))) -> OK - capacidade suficiente | T14: =AUX_MATRIZES!K152 -> 0.086363108 | U14: =AUX_MATRIZES!K153 -> TR01 | V14: =IF($T14>LIMITE_CRITICO,"INVIAVEL - demanda excede a capacidade em 21 h/dia",IF($T14>LIMITE_ATENCAO,"CRITICO - utilizacao acima de "&TEXT(LIMITE_ATENCAO,"0%"),IF($T14>LIMITE_CONFORTAVEL,"ATENCAO - utilizacao acima de "&TEXT(LIMITE_CONFORTAVEL,"0%"),"OK - capacidade suficiente"))) -> OK - capacidade suficiente | W14: =AUX_MATRIZES!K161 -> 101846.33
B15: =SEMANAS!$B$15 -> 10 | C15: =SEMANAS!$C$15 -> 46328 | D15: =SEMANAS!$D$15 -> 46334 | E15: =AUX_MATRIZES!L140 -> 0 | F15: =AUX_MATRIZES!L156*SEMANAS!$K$15 -> 4470818.1 | G15: =IFERROR($E15/$F15,0) -> 0 | H15: =MAX(0,$E15-$F15) -> 0 | I15: =AUX_MATRIZES!L158 -> 0 | J15: =AUX_MATRIZES!L160 -> 0 | K15: =IFERROR(MAX(0,$E15/AUX_MATRIZES!L156-SEMANAS!$K$15),0) -> 0 | L15: =IFERROR(MAX(0,$E15/SEMANAS!$K$15-AUX_MATRIZES!L156),0) -> 0 | M15: =IF($G15>LIMITE_CRITICO,"INVIAVEL - demanda excede a capacidade em 21 h/dia",IF($G15>LIMITE_ATENCAO,"CRITICO - utilizacao acima de "&TEXT(LIMITE_ATENCAO,"0%"),IF($G15>LIMITE_CONFORTAVEL,"ATENCAO - utilizacao acima de "&TEXT(LIMITE_CONFORTAVEL,"0%"),"OK - capacidade suficiente"))) -> OK - capacidade suficiente | N15: =AUX_MATRIZES!L148 -> 0 | O15: =AUX_MATRIZES!L149 -> PV 109 | P15: =IF($N15>LIMITE_CRITICO,"INVIAVEL - demanda excede a capacidade em 21 h/dia",IF($N15>LIMITE_ATENCAO,"CRITICO - utilizacao acima de "&TEXT(LIMITE_ATENCAO,"0%"),IF($N15>LIMITE_CONFORTAVEL,"ATENCAO - utilizacao acima de "&TEXT(LIMITE_CONFORTAVEL,"0%"),"OK - capacidade suficiente"))) -> OK - capacidade suficiente | Q15: =AUX_MATRIZES!L150 -> 0 | R15: =AUX_MATRIZES!L151 -> RM01 | S15: =IF($Q15>LIMITE_CRITICO,"INVIAVEL - demanda excede a capacidade em 21 h/dia",IF($Q15>LIMITE_ATENCAO,"CRITICO - utilizacao acima de "&TEXT(LIMITE_ATENCAO,"0%"),IF($Q15>LIMITE_CONFORTAVEL,"ATENCAO - utilizacao acima de "&TEXT(LIMITE_CONFORTAVEL,"0%"),"OK - capacidade suficiente"))) -> OK - capacidade suficiente | T15: =AUX_MATRIZES!L152 -> 0 | U15: =AUX_MATRIZES!L153 -> TR01 | V15: =IF($T15>LIMITE_CRITICO,"INVIAVEL - demanda excede a capacidade em 21 h/dia",IF($T15>LIMITE_ATENCAO,"CRITICO - utilizacao acima de "&TEXT(LIMITE_ATENCAO,"0%"),IF($T15>LIMITE_CONFORTAVEL,"ATENCAO - utilizacao acima de "&TEXT(LIMITE_CONFORTAVEL,"0%"),"OK - capacidade suficiente"))) -> OK - capacidade suficiente | W15: =AUX_MATRIZES!L161 -> 1e-05
B16: =SEMANAS!$B$16 -> 11 | C16: =SEMANAS!$C$16 -> 46335 | D16: =SEMANAS!$D$16 -> 46341 | E16: =AUX_MATRIZES!M140 -> 14677.596 | F16: =AUX_MATRIZES!M156*SEMANAS!$K$16 -> 4470818.1 | G16: =IFERROR($E16/$F16,0) -> 0.0032829776 | H16: =MAX(0,$E16-$F16) -> 0 | I16: =AUX_MATRIZES!M158 -> 0 | J16: =AUX_MATRIZES!M160 -> 0 | K16: =IFERROR(MAX(0,$E16/AUX_MATRIZES!M156-SEMANAS!$K$16),0) -> 0 | L16: =IFERROR(MAX(0,$E16/SEMANAS!$K$16-AUX_MATRIZES!M156),0) -> 0 | M16: =IF($G16>LIMITE_CRITICO,"INVIAVEL - demanda excede a capacidade em 21 h/dia",IF($G16>LIMITE_ATENCAO,"CRITICO - utilizacao acima de "&TEXT(LIMITE_ATENCAO,"0%"),IF($G16>LIMITE_CONFORTAVEL,"ATENCAO - utilizacao acima de "&TEXT(LIMITE_CONFORTAVEL,"0%"),"OK - capacidade suficiente"))) -> OK - capacidade suficiente | N16: =AUX_MATRIZES!M148 -> 0.02345098 | O16: =AUX_MATRIZES!M149 -> PV 109 | P16: =IF($N16>LIMITE_CRITICO,"INVIAVEL - demanda excede a capacidade em 21 h/dia",IF($N16>LIMITE_ATENCAO,"CRITICO - utilizacao acima de "&TEXT(LIMITE_ATENCAO,"0%"),IF($N16>LIMITE_CONFORTAVEL,"ATENCAO - utilizacao acima de "&TEXT(LIMITE_CONFORTAVEL,"0%"),"OK - capacidade suficiente"))) -> OK - capacidade suficiente | Q16: =AUX_MATRIZES!M150 -> 0.02345098 | R16: =AUX_MATRIZES!M151 -> RM01 | S16: =IF($Q16>LIMITE_CRITICO,"INVIAVEL - demanda excede a capacidade em 21 h/dia",IF($Q16>LIMITE_ATENCAO,"CRITICO - utilizacao acima de "&TEXT(LIMITE_ATENCAO,"0%"),IF($Q16>LIMITE_CONFORTAVEL,"ATENCAO - utilizacao acima de "&TEXT(LIMITE_CONFORTAVEL,"0%"),"OK - capacidade suficiente"))) -> OK - capacidade suficiente | T16: =AUX_MATRIZES!M152 -> 0.02345098 | U16: =AUX_MATRIZES!M153 -> TR01 | V16: =IF($T16>LIMITE_CRITICO,"INVIAVEL - demanda excede a capacidade em 21 h/dia",IF($T16>LIMITE_ATENCAO,"CRITICO - utilizacao acima de "&TEXT(LIMITE_ATENCAO,"0%"),IF($T16>LIMITE_CONFORTAVEL,"ATENCAO - utilizacao acima de "&TEXT(LIMITE_CONFORTAVEL,"0%"),"OK - capacidade suficiente"))) -> OK - capacidade suficiente | W16: =AUX_MATRIZES!M161 -> 14677.596
B17: =SEMANAS!$B$17 -> 12 | C17: =SEMANAS!$C$17 -> 46342 | D17: =SEMANAS!$D$17 -> 46348 | E17: =AUX_MATRIZES!N140 -> 14948.698 | F17: =AUX_MATRIZES!N156*SEMANAS!$K$17 -> 4470818.1 | G17: =IFERROR($E17/$F17,0) -> 0.0033436159 | H17: =MAX(0,$E17-$F17) -> 0 | I17: =AUX_MATRIZES!N158 -> 0 | J17: =AUX_MATRIZES!N160 -> 0 | K17: =IFERROR(MAX(0,$E17/AUX_MATRIZES!N156-SEMANAS!$K$17),0) -> 0 | L17: =IFERROR(MAX(0,$E17/SEMANAS!$K$17-AUX_MATRIZES!N156),0) -> 0 | M17: =IF($G17>LIMITE_CRITICO,"INVIAVEL - demanda excede a capacidade em 21 h/dia",IF($G17>LIMITE_ATENCAO,"CRITICO - utilizacao acima de "&TEXT(LIMITE_ATENCAO,"0%"),IF($G17>LIMITE_CONFORTAVEL,"ATENCAO - utilizacao acima de "&TEXT(LIMITE_CONFORTAVEL,"0%"),"OK - capacidade suficiente"))) -> OK - capacidade suficiente | N17: =AUX_MATRIZES!N148 -> 0.02345098 | O17: =AUX_MATRIZES!N149 -> PV 109 | P17: =IF($N17>LIMITE_CRITICO,"INVIAVEL - demanda excede a capacidade em 21 h/dia",IF($N17>LIMITE_ATENCAO,"CRITICO - utilizacao acima de "&TEXT(LIMITE_ATENCAO,"0%"),IF($N17>LIMITE_CONFORTAVEL,"ATENCAO - utilizacao acima de "&TEXT(LIMITE_CONFORTAVEL,"0%"),"OK - capacidade suficiente"))) -> OK - capacidade suficiente | Q17: =AUX_MATRIZES!N150 -> 0.02345098 | R17: =AUX_MATRIZES!N151 -> RM01 | S17: =IF($Q17>LIMITE_CRITICO,"INVIAVEL - demanda excede a capacidade em 21 h/dia",IF($Q17>LIMITE_ATENCAO,"CRITICO - utilizacao acima de "&TEXT(LIMITE_ATENCAO,"0%"),IF($Q17>LIMITE_CONFORTAVEL,"ATENCAO - utilizacao acima de "&TEXT(LIMITE_CONFORTAVEL,"0%"),"OK - capacidade suficiente"))) -> OK - capacidade suficiente | T17: =AUX_MATRIZES!N152 -> 0.02345098 | U17: =AUX_MATRIZES!N153 -> TR01 | V17: =IF($T17>LIMITE_CRITICO,"INVIAVEL - demanda excede a capacidade em 21 h/dia",IF($T17>LIMITE_ATENCAO,"CRITICO - utilizacao acima de "&TEXT(LIMITE_ATENCAO,"0%"),IF($T17>LIMITE_CONFORTAVEL,"ATENCAO - utilizacao acima de "&TEXT(LIMITE_CONFORTAVEL,"0%"),"OK - capacidade suficiente"))) -> OK - capacidade suficiente | W17: =AUX_MATRIZES!N161 -> 14948.698
B18: =SEMANAS!$B$18 -> 13 | C18: =SEMANAS!$C$18 -> 46349 | D18: =SEMANAS!$D$18 -> 46355 | E18: =AUX_MATRIZES!O140 -> 23618.658 | F18: =AUX_MATRIZES!O156*SEMANAS!$K$18 -> 4470818.1 | G18: =IFERROR($E18/$F18,0) -> 0.0052828492 | H18: =MAX(0,$E18-$F18) -> 0 | I18: =AUX_MATRIZES!O158 -> 0 | J18: =AUX_MATRIZES!O160 -> 0 | K18: =IFERROR(MAX(0,$E18/AUX_MATRIZES!O156-SEMANAS!$K$18),0) -> 0 | L18: =IFERROR(MAX(0,$E18/SEMANAS!$K$18-AUX_MATRIZES!O156),0) -> 0 | M18: =IF($G18>LIMITE_CRITICO,"INVIAVEL - demanda excede a capacidade em 21 h/dia",IF($G18>LIMITE_ATENCAO,"CRITICO - utilizacao acima de "&TEXT(LIMITE_ATENCAO,"0%"),IF($G18>LIMITE_CONFORTAVEL,"ATENCAO - utilizacao acima de "&TEXT(LIMITE_CONFORTAVEL,"0%"),"OK - capacidade suficiente"))) -> OK - capacidade suficiente | N18: =AUX_MATRIZES!O148 -> 0.024067107 | O18: =AUX_MATRIZES!O149 -> PV 113 | P18: =IF($N18>LIMITE_CRITICO,"INVIAVEL - demanda excede a capacidade em 21 h/dia",IF($N18>LIMITE_ATENCAO,"CRITICO - utilizacao acima de "&TEXT(LIMITE_ATENCAO,"0%"),IF($N18>LIMITE_CONFORTAVEL,"ATENCAO - utilizacao acima de "&TEXT(LIMITE_CONFORTAVEL,"0%"),"OK - capacidade suficiente"))) -> OK - capacidade suficiente | Q18: =AUX_MATRIZES!O150 -> 0.02345098 | R18: =AUX_MATRIZES!O151 -> RM01 | S18: =IF($Q18>LIMITE_CRITICO,"INVIAVEL - demanda excede a capacidade em 21 h/dia",IF($Q18>LIMITE_ATENCAO,"CRITICO - utilizacao acima de "&TEXT(LIMITE_ATENCAO,"0%"),IF($Q18>LIMITE_CONFORTAVEL,"ATENCAO - utilizacao acima de "&TEXT(LIMITE_CONFORTAVEL,"0%"),"OK - capacidade suficiente"))) -> OK - capacidade suficiente | T18: =AUX_MATRIZES!O152 -> 0.02345098 | U18: =AUX_MATRIZES!O153 -> TR01 | V18: =IF($T18>LIMITE_CRITICO,"INVIAVEL - demanda excede a capacidade em 21 h/dia",IF($T18>LIMITE_ATENCAO,"CRITICO - utilizacao acima de "&TEXT(LIMITE_ATENCAO,"0%"),IF($T18>LIMITE_CONFORTAVEL,"ATENCAO - utilizacao acima de "&TEXT(LIMITE_CONFORTAVEL,"0%"),"OK - capacidade suficiente"))) -> OK - capacidade suficiente | W18: =AUX_MATRIZES!O161 -> 23618.658
B19: =SEMANAS!$B$19 -> 14 | C19: =SEMANAS!$C$19 -> 46356 | D19: =SEMANAS!$D$19 -> 46362 | E19: =AUX_MATRIZES!P140 -> 0 | F19: =AUX_MATRIZES!P156*SEMANAS!$K$19 -> 4470818.1 | G19: =IFERROR($E19/$F19,0) -> 0 | H19: =MAX(0,$E19-$F19) -> 0 | I19: =AUX_MATRIZES!P158 -> 0 | J19: =AUX_MATRIZES!P160 -> 0 | K19: =IFERROR(MAX(0,$E19/AUX_MATRIZES!P156-SEMANAS!$K$19),0) -> 0 | L19: =IFERROR(MAX(0,$E19/SEMANAS!$K$19-AUX_MATRIZES!P156),0) -> 0 | M19: =IF($G19>LIMITE_CRITICO,"INVIAVEL - demanda excede a capacidade em 21 h/dia",IF($G19>LIMITE_ATENCAO,"CRITICO - utilizacao acima de "&TEXT(LIMITE_ATENCAO,"0%"),IF($G19>LIMITE_CONFORTAVEL,"ATENCAO - utilizacao acima de "&TEXT(LIMITE_CONFORTAVEL,"0%"),"OK - capacidade suficiente"))) -> OK - capacidade suficiente | N19: =AUX_MATRIZES!P148 -> 0 | O19: =AUX_MATRIZES!P149 -> PV 109 | P19: =IF($N19>LIMITE_CRITICO,"INVIAVEL - demanda excede a capacidade em 21 h/dia",IF($N19>LIMITE_ATENCAO,"CRITICO - utilizacao acima de "&TEXT(LIMITE_ATENCAO,"0%"),IF($N19>LIMITE_CONFORTAVEL,"ATENCAO - utilizacao acima de "&TEXT(LIMITE_CONFORTAVEL,"0%"),"OK - capacidade suficiente"))) -> OK - capacidade suficiente | Q19: =AUX_MATRIZES!P150 -> 0 | R19: =AUX_MATRIZES!P151 -> RM01 | S19: =IF($Q19>LIMITE_CRITICO,"INVIAVEL - demanda excede a capacidade em 21 h/dia",IF($Q19>LIMITE_ATENCAO,"CRITICO - utilizacao acima de "&TEXT(LIMITE_ATENCAO,"0%"),IF($Q19>LIMITE_CONFORTAVEL,"ATENCAO - utilizacao acima de "&TEXT(LIMITE_CONFORTAVEL,"0%"),"OK - capacidade suficiente"))) -> OK - capacidade suficiente | T19: =AUX_MATRIZES!P152 -> 0 | U19: =AUX_MATRIZES!P153 -> TR01 | V19: =IF($T19>LIMITE_CRITICO,"INVIAVEL - demanda excede a capacidade em 21 h/dia",IF($T19>LIMITE_ATENCAO,"CRITICO - utilizacao acima de "&TEXT(LIMITE_ATENCAO,"0%"),IF($T19>LIMITE_CONFORTAVEL,"ATENCAO - utilizacao acima de "&TEXT(LIMITE_CONFORTAVEL,"0%"),"OK - capacidade suficiente"))) -> OK - capacidade suficiente | W19: =AUX_MATRIZES!P161 -> 1.4e-05
B20: =SEMANAS!$B$20 -> 15 | C20: =SEMANAS!$C$20 -> 46363 | D20: =SEMANAS!$D$20 -> 46369 | E20: =AUX_MATRIZES!Q140 -> 0 | F20: =AUX_MATRIZES!Q156*SEMANAS!$K$20 -> 4470818.1 | G20: =IFERROR($E20/$F20,0) -> 0 | H20: =MAX(0,$E20-$F20) -> 0 | I20: =AUX_MATRIZES!Q158 -> 0 | J20: =AUX_MATRIZES!Q160 -> 0 | K20: =IFERROR(MAX(0,$E20/AUX_MATRIZES!Q156-SEMANAS!$K$20),0) -> 0 | L20: =IFERROR(MAX(0,$E20/SEMANAS!$K$20-AUX_MATRIZES!Q156),0) -> 0 | M20: =IF($G20>LIMITE_CRITICO,"INVIAVEL - demanda excede a capacidade em 21 h/dia",IF($G20>LIMITE_ATENCAO,"CRITICO - utilizacao acima de "&TEXT(LIMITE_ATENCAO,"0%"),IF($G20>LIMITE_CONFORTAVEL,"ATENCAO - utilizacao acima de "&TEXT(LIMITE_CONFORTAVEL,"0%"),"OK - capacidade suficiente"))) -> OK - capacidade suficiente | N20: =AUX_MATRIZES!Q148 -> 0 | O20: =AUX_MATRIZES!Q149 -> PV 109 | P20: =IF($N20>LIMITE_CRITICO,"INVIAVEL - demanda excede a capacidade em 21 h/dia",IF($N20>LIMITE_ATENCAO,"CRITICO - utilizacao acima de "&TEXT(LIMITE_ATENCAO,"0%"),IF($N20>LIMITE_CONFORTAVEL,"ATENCAO - utilizacao acima de "&TEXT(LIMITE_CONFORTAVEL,"0%"),"OK - capacidade suficiente"))) -> OK - capacidade suficiente | Q20: =AUX_MATRIZES!Q150 -> 0 | R20: =AUX_MATRIZES!Q151 -> RM01 | S20: =IF($Q20>LIMITE_CRITICO,"INVIAVEL - demanda excede a capacidade em 21 h/dia",IF($Q20>LIMITE_ATENCAO,"CRITICO - utilizacao acima de "&TEXT(LIMITE_ATENCAO,"0%"),IF($Q20>LIMITE_CONFORTAVEL,"ATENCAO - utilizacao acima de "&TEXT(LIMITE_CONFORTAVEL,"0%"),"OK - capacidade suficiente"))) -> OK - capacidade suficiente | T20: =AUX_MATRIZES!Q152 -> 0 | U20: =AUX_MATRIZES!Q153 -> TR01 | V20: =IF($T20>LIMITE_CRITICO,"INVIAVEL - demanda excede a capacidade em 21 h/dia",IF($T20>LIMITE_ATENCAO,"CRITICO - utilizacao acima de "&TEXT(LIMITE_ATENCAO,"0%"),IF($T20>LIMITE_CONFORTAVEL,"ATENCAO - utilizacao acima de "&TEXT(LIMITE_CONFORTAVEL,"0%"),"OK - capacidade suficiente"))) -> OK - capacidade suficiente | W20: =AUX_MATRIZES!Q161 -> 1.5e-05
B21: =SEMANAS!$B$21 -> 16 | C21: =SEMANAS!$C$21 -> 46370 | D21: =SEMANAS!$D$21 -> 46376 | E21: =AUX_MATRIZES!R140 -> 0 | F21: =AUX_MATRIZES!R156*SEMANAS!$K$21 -> 4470818.1 | G21: =IFERROR($E21/$F21,0) -> 0 | H21: =MAX(0,$E21-$F21) -> 0 | I21: =AUX_MATRIZES!R158 -> 0 | J21: =AUX_MATRIZES!R160 -> 0 | K21: =IFERROR(MAX(0,$E21/AUX_MATRIZES!R156-SEMANAS!$K$21),0) -> 0 | L21: =IFERROR(MAX(0,$E21/SEMANAS!$K$21-AUX_MATRIZES!R156),0) -> 0 | M21: =IF($G21>LIMITE_CRITICO,"INVIAVEL - demanda excede a capacidade em 21 h/dia",IF($G21>LIMITE_ATENCAO,"CRITICO - utilizacao acima de "&TEXT(LIMITE_ATENCAO,"0%"),IF($G21>LIMITE_CONFORTAVEL,"ATENCAO - utilizacao acima de "&TEXT(LIMITE_CONFORTAVEL,"0%"),"OK - capacidade suficiente"))) -> OK - capacidade suficiente | N21: =AUX_MATRIZES!R148 -> 0 | O21: =AUX_MATRIZES!R149 -> PV 109 | P21: =IF($N21>LIMITE_CRITICO,"INVIAVEL - demanda excede a capacidade em 21 h/dia",IF($N21>LIMITE_ATENCAO,"CRITICO - utilizacao acima de "&TEXT(LIMITE_ATENCAO,"0%"),IF($N21>LIMITE_CONFORTAVEL,"ATENCAO - utilizacao acima de "&TEXT(LIMITE_CONFORTAVEL,"0%"),"OK - capacidade suficiente"))) -> OK - capacidade suficiente | Q21: =AUX_MATRIZES!R150 -> 0 | R21: =AUX_MATRIZES!R151 -> RM01 | S21: =IF($Q21>LIMITE_CRITICO,"INVIAVEL - demanda excede a capacidade em 21 h/dia",IF($Q21>LIMITE_ATENCAO,"CRITICO - utilizacao acima de "&TEXT(LIMITE_ATENCAO,"0%"),IF($Q21>LIMITE_CONFORTAVEL,"ATENCAO - utilizacao acima de "&TEXT(LIMITE_CONFORTAVEL,"0%"),"OK - capacidade suficiente"))) -> OK - capacidade suficiente | T21: =AUX_MATRIZES!R152 -> 0 | U21: =AUX_MATRIZES!R153 -> TR01 | V21: =IF($T21>LIMITE_CRITICO,"INVIAVEL - demanda excede a capacidade em 21 h/dia",IF($T21>LIMITE_ATENCAO,"CRITICO - utilizacao acima de "&TEXT(LIMITE_ATENCAO,"0%"),IF($T21>LIMITE_CONFORTAVEL,"ATENCAO - utilizacao acima de "&TEXT(LIMITE_CONFORTAVEL,"0%"),"OK - capacidade suficiente"))) -> OK - capacidade suficiente | W21: =AUX_MATRIZES!R161 -> 1.6e-05
B22: =SEMANAS!$B$22 -> 17 | C22: =SEMANAS!$C$22 -> 46377 | D22: =SEMANAS!$D$22 -> 46383 | E22: =AUX_MATRIZES!S140 -> 0 | F22: =AUX_MATRIZES!S156*SEMANAS!$K$22 -> 4470818.1 | G22: =IFERROR($E22/$F22,0) -> 0 | H22: =MAX(0,$E22-$F22) -> 0 | I22: =AUX_MATRIZES!S158 -> 0 | J22: =AUX_MATRIZES!S160 -> 0 | K22: =IFERROR(MAX(0,$E22/AUX_MATRIZES!S156-SEMANAS!$K$22),0) -> 0 | L22: =IFERROR(MAX(0,$E22/SEMANAS!$K$22-AUX_MATRIZES!S156),0) -> 0 | M22: =IF($G22>LIMITE_CRITICO,"INVIAVEL - demanda excede a capacidade em 21 h/dia",IF($G22>LIMITE_ATENCAO,"CRITICO - utilizacao acima de "&TEXT(LIMITE_ATENCAO,"0%"),IF($G22>LIMITE_CONFORTAVEL,"ATENCAO - utilizacao acima de "&TEXT(LIMITE_CONFORTAVEL,"0%"),"OK - capacidade suficiente"))) -> OK - capacidade suficiente | N22: =AUX_MATRIZES!S148 -> 0 | O22: =AUX_MATRIZES!S149 -> PV 109 | P22: =IF($N22>LIMITE_CRITICO,"INVIAVEL - demanda excede a capacidade em 21 h/dia",IF($N22>LIMITE_ATENCAO,"CRITICO - utilizacao acima de "&TEXT(LIMITE_ATENCAO,"0%"),IF($N22>LIMITE_CONFORTAVEL,"ATENCAO - utilizacao acima de "&TEXT(LIMITE_CONFORTAVEL,"0%"),"OK - capacidade suficiente"))) -> OK - capacidade suficiente | Q22: =AUX_MATRIZES!S150 -> 0 | R22: =AUX_MATRIZES!S151 -> RM01 | S22: =IF($Q22>LIMITE_CRITICO,"INVIAVEL - demanda excede a capacidade em 21 h/dia",IF($Q22>LIMITE_ATENCAO,"CRITICO - utilizacao acima de "&TEXT(LIMITE_ATENCAO,"0%"),IF($Q22>LIMITE_CONFORTAVEL,"ATENCAO - utilizacao acima de "&TEXT(LIMITE_CONFORTAVEL,"0%"),"OK - capacidade suficiente"))) -> OK - capacidade suficiente | T22: =AUX_MATRIZES!S152 -> 0 | U22: =AUX_MATRIZES!S153 -> TR01 | V22: =IF($T22>LIMITE_CRITICO,"INVIAVEL - demanda excede a capacidade em 21 h/dia",IF($T22>LIMITE_ATENCAO,"CRITICO - utilizacao acima de "&TEXT(LIMITE_ATENCAO,"0%"),IF($T22>LIMITE_CONFORTAVEL,"ATENCAO - utilizacao acima de "&TEXT(LIMITE_CONFORTAVEL,"0%"),"OK - capacidade suficiente"))) -> OK - capacidade suficiente | W22: =AUX_MATRIZES!S161 -> 1.7e-05
B23: =SEMANAS!$B$23 -> 18 | C23: =SEMANAS!$C$23 -> 46384 | D23: =SEMANAS!$D$23 -> 46390 | E23: =AUX_MATRIZES!T140 -> 6872.8524 | F23: =AUX_MATRIZES!T156*SEMANAS!$K$23 -> 4470818.1 | G23: =IFERROR($E23/$F23,0) -> 0.0015372695 | H23: =MAX(0,$E23-$F23) -> 0 | I23: =AUX_MATRIZES!T158 -> 0 | J23: =AUX_MATRIZES!T160 -> 0 | K23: =IFERROR(MAX(0,$E23/AUX_MATRIZES!T156-SEMANAS!$K$23),0) -> 0 | L23: =IFERROR(MAX(0,$E23/SEMANAS!$K$23-AUX_MATRIZES!T156),0) -> 0 | M23: =IF($G23>LIMITE_CRITICO,"INVIAVEL - demanda excede a capacidade em 21 h/dia",IF($G23>LIMITE_ATENCAO,"CRITICO - utilizacao acima de "&TEXT(LIMITE_ATENCAO,"0%"),IF($G23>LIMITE_CONFORTAVEL,"ATENCAO - utilizacao acima de "&TEXT(LIMITE_CONFORTAVEL,"0%"),"OK - capacidade suficiente"))) -> OK - capacidade suficiente | N23: =AUX_MATRIZES!T148 -> 0.0063606981 | O23: =AUX_MATRIZES!T149 -> PV 113 | P23: =IF($N23>LIMITE_CRITICO,"INVIAVEL - demanda excede a capacidade em 21 h/dia",IF($N23>LIMITE_ATENCAO,"CRITICO - utilizacao acima de "&TEXT(LIMITE_ATENCAO,"0%"),IF($N23>LIMITE_CONFORTAVEL,"ATENCAO - utilizacao acima de "&TEXT(LIMITE_CONFORTAVEL,"0%"),"OK - capacidade suficiente"))) -> OK - capacidade suficiente | Q23: =AUX_MATRIZES!T150 -> 0.0033037596 | R23: =AUX_MATRIZES!T151 -> RM07 | S23: =IF($Q23>LIMITE_CRITICO,"INVIAVEL - demanda excede a capacidade em 21 h/dia",IF($Q23>LIMITE_ATENCAO,"CRITICO - utilizacao acima de "&TEXT(LIMITE_ATENCAO,"0%"),IF($Q23>LIMITE_CONFORTAVEL,"ATENCAO - utilizacao acima de "&TEXT(LIMITE_CONFORTAVEL,"0%"),"OK - capacidade suficiente"))) -> OK - capacidade suficiente | T23: =AUX_MATRIZES!T152 -> 0.0033037596 | U23: =AUX_MATRIZES!T153 -> TR07 | V23: =IF($T23>LIMITE_CRITICO,"INVIAVEL - demanda excede a capacidade em 21 h/dia",IF($T23>LIMITE_ATENCAO,"CRITICO - utilizacao acima de "&TEXT(LIMITE_ATENCAO,"0%"),IF($T23>LIMITE_CONFORTAVEL,"ATENCAO - utilizacao acima de "&TEXT(LIMITE_CONFORTAVEL,"0%"),"OK - capacidade suficiente"))) -> OK - capacidade suficiente | W23: =AUX_MATRIZES!T161 -> 6872.8524
B24: =SEMANAS!$B$24 -> 19 | C24: =SEMANAS!$C$24 -> 46391 | D24: =SEMANAS!$D$24 -> 46397 | E24: =AUX_MATRIZES!U140 -> 32485.172 | F24: =AUX_MATRIZES!U156*SEMANAS!$K$24 -> 4470818.1 | G24: =IFERROR($E24/$F24,0) -> 0.0072660464 | H24: =MAX(0,$E24-$F24) -> 0 | I24: =AUX_MATRIZES!U158 -> 0 | J24: =AUX_MATRIZES!U160 -> 0 | K24: =IFERROR(MAX(0,$E24/AUX_MATRIZES!U156-SEMANAS!$K$24),0) -> 0 | L24: =IFERROR(MAX(0,$E24/SEMANAS!$K$24-AUX_MATRIZES!U156),0) -> 0 | M24: =IF($G24>LIMITE_CRITICO,"INVIAVEL - demanda excede a capacidade em 21 h/dia",IF($G24>LIMITE_ATENCAO,"CRITICO - utilizacao acima de "&TEXT(LIMITE_ATENCAO,"0%"),IF($G24>LIMITE_CONFORTAVEL,"ATENCAO - utilizacao acima de "&TEXT(LIMITE_CONFORTAVEL,"0%"),"OK - capacidade suficiente"))) -> OK - capacidade suficiente | N24: =AUX_MATRIZES!U148 -> 0.032579186 | O24: =AUX_MATRIZES!U149 -> PV 113 | P24: =IF($N24>LIMITE_CRITICO,"INVIAVEL - demanda excede a capacidade em 21 h/dia",IF($N24>LIMITE_ATENCAO,"CRITICO - utilizacao acima de "&TEXT(LIMITE_ATENCAO,"0%"),IF($N24>LIMITE_CONFORTAVEL,"ATENCAO - utilizacao acima de "&TEXT(LIMITE_CONFORTAVEL,"0%"),"OK - capacidade suficiente"))) -> OK - capacidade suficiente | Q24: =AUX_MATRIZES!U150 -> 0.016921695 | R24: =AUX_MATRIZES!U151 -> RM07 | S24: =IF($Q24>LIMITE_CRITICO,"INVIAVEL - demanda excede a capacidade em 21 h/dia",IF($Q24>LIMITE_ATENCAO,"CRITICO - utilizacao acima de "&TEXT(LIMITE_ATENCAO,"0%"),IF($Q24>LIMITE_CONFORTAVEL,"ATENCAO - utilizacao acima de "&TEXT(LIMITE_CONFORTAVEL,"0%"),"OK - capacidade suficiente"))) -> OK - capacidade suficiente | T24: =AUX_MATRIZES!U152 -> 0.016921695 | U24: =AUX_MATRIZES!U153 -> TR07 | V24: =IF($T24>LIMITE_CRITICO,"INVIAVEL - demanda excede a capacidade em 21 h/dia",IF($T24>LIMITE_ATENCAO,"CRITICO - utilizacao acima de "&TEXT(LIMITE_ATENCAO,"0%"),IF($T24>LIMITE_CONFORTAVEL,"ATENCAO - utilizacao acima de "&TEXT(LIMITE_CONFORTAVEL,"0%"),"OK - capacidade suficiente"))) -> OK - capacidade suficiente | W24: =AUX_MATRIZES!U161 -> 32485.172
B25: =SEMANAS!$B$25 -> 20 | C25: =SEMANAS!$C$25 -> 46398 | D25: =SEMANAS!$D$25 -> 46404 | E25: =AUX_MATRIZES!V140 -> 32345.295 | F25: =AUX_MATRIZES!V156*SEMANAS!$K$25 -> 4470818.1 | G25: =IFERROR($E25/$F25,0) -> 0.0072347598 | H25: =MAX(0,$E25-$F25) -> 0 | I25: =AUX_MATRIZES!V158 -> 0 | J25: =AUX_MATRIZES!V160 -> 0 | K25: =IFERROR(MAX(0,$E25/AUX_MATRIZES!V156-SEMANAS!$K$25),0) -> 0 | L25: =IFERROR(MAX(0,$E25/SEMANAS!$K$25-AUX_MATRIZES!V156),0) -> 0 | M25: =IF($G25>LIMITE_CRITICO,"INVIAVEL - demanda excede a capacidade em 21 h/dia",IF($G25>LIMITE_ATENCAO,"CRITICO - utilizacao acima de "&TEXT(LIMITE_ATENCAO,"0%"),IF($G25>LIMITE_CONFORTAVEL,"ATENCAO - utilizacao acima de "&TEXT(LIMITE_CONFORTAVEL,"0%"),"OK - capacidade suficiente"))) -> OK - capacidade suficiente | N25: =AUX_MATRIZES!V148 -> 0.032066748 | O25: =AUX_MATRIZES!V149 -> PV 113 | P25: =IF($N25>LIMITE_CRITICO,"INVIAVEL - demanda excede a capacidade em 21 h/dia",IF($N25>LIMITE_ATENCAO,"CRITICO - utilizacao acima de "&TEXT(LIMITE_ATENCAO,"0%"),IF($N25>LIMITE_CONFORTAVEL,"ATENCAO - utilizacao acima de "&TEXT(LIMITE_CONFORTAVEL,"0%"),"OK - capacidade suficiente"))) -> OK - capacidade suficiente | Q25: =AUX_MATRIZES!V150 -> 0.016921695 | R25: =AUX_MATRIZES!V151 -> RM07 | S25: =IF($Q25>LIMITE_CRITICO,"INVIAVEL - demanda excede a capacidade em 21 h/dia",IF($Q25>LIMITE_ATENCAO,"CRITICO - utilizacao acima de "&TEXT(LIMITE_ATENCAO,"0%"),IF($Q25>LIMITE_CONFORTAVEL,"ATENCAO - utilizacao acima de "&TEXT(LIMITE_CONFORTAVEL,"0%"),"OK - capacidade suficiente"))) -> OK - capacidade suficiente | T25: =AUX_MATRIZES!V152 -> 0.016921695 | U25: =AUX_MATRIZES!V153 -> TR07 | V25: =IF($T25>LIMITE_CRITICO,"INVIAVEL - demanda excede a capacidade em 21 h/dia",IF($T25>LIMITE_ATENCAO,"CRITICO - utilizacao acima de "&TEXT(LIMITE_ATENCAO,"0%"),IF($T25>LIMITE_CONFORTAVEL,"ATENCAO - utilizacao acima de "&TEXT(LIMITE_CONFORTAVEL,"0%"),"OK - capacidade suficiente"))) -> OK - capacidade suficiente | W25: =AUX_MATRIZES!V161 -> 32345.295
B26: =SEMANAS!$B$26 -> 21 | C26: =SEMANAS!$C$26 -> 46405 | D26: =SEMANAS!$D$26 -> 46411 | E26: =AUX_MATRIZES!W140 -> 8508.7164 | F26: =AUX_MATRIZES!W156*SEMANAS!$K$26 -> 4470818.1 | G26: =IFERROR($E26/$F26,0) -> 0.0019031676 | H26: =MAX(0,$E26-$F26) -> 0 | I26: =AUX_MATRIZES!W158 -> 0 | J26: =AUX_MATRIZES!W160 -> 0 | K26: =IFERROR(MAX(0,$E26/AUX_MATRIZES!W156-SEMANAS!$K$26),0) -> 0 | L26: =IFERROR(MAX(0,$E26/SEMANAS!$K$26-AUX_MATRIZES!W156),0) -> 0 | M26: =IF($G26>LIMITE_CRITICO,"INVIAVEL - demanda excede a capacidade em 21 h/dia",IF($G26>LIMITE_ATENCAO,"CRITICO - utilizacao acima de "&TEXT(LIMITE_ATENCAO,"0%"),IF($G26>LIMITE_CONFORTAVEL,"ATENCAO - utilizacao acima de "&TEXT(LIMITE_CONFORTAVEL,"0%"),"OK - capacidade suficiente"))) -> OK - capacidade suficiente | N26: =AUX_MATRIZES!W148 -> 0.028235294 | O26: =AUX_MATRIZES!W149 -> PV 124 | P26: =IF($N26>LIMITE_CRITICO,"INVIAVEL - demanda excede a capacidade em 21 h/dia",IF($N26>LIMITE_ATENCAO,"CRITICO - utilizacao acima de "&TEXT(LIMITE_ATENCAO,"0%"),IF($N26>LIMITE_CONFORTAVEL,"ATENCAO - utilizacao acima de "&TEXT(LIMITE_CONFORTAVEL,"0%"),"OK - capacidade suficiente"))) -> OK - capacidade suficiente | Q26: =AUX_MATRIZES!W150 -> 0.0069748705 | R26: =AUX_MATRIZES!W151 -> RM07 | S26: =IF($Q26>LIMITE_CRITICO,"INVIAVEL - demanda excede a capacidade em 21 h/dia",IF($Q26>LIMITE_ATENCAO,"CRITICO - utilizacao acima de "&TEXT(LIMITE_ATENCAO,"0%"),IF($Q26>LIMITE_CONFORTAVEL,"ATENCAO - utilizacao acima de "&TEXT(LIMITE_CONFORTAVEL,"0%"),"OK - capacidade suficiente"))) -> OK - capacidade suficiente | T26: =AUX_MATRIZES!W152 -> 0.0069748705 | U26: =AUX_MATRIZES!W153 -> TR07 | V26: =IF($T26>LIMITE_CRITICO,"INVIAVEL - demanda excede a capacidade em 21 h/dia",IF($T26>LIMITE_ATENCAO,"CRITICO - utilizacao acima de "&TEXT(LIMITE_ATENCAO,"0%"),IF($T26>LIMITE_CONFORTAVEL,"ATENCAO - utilizacao acima de "&TEXT(LIMITE_CONFORTAVEL,"0%"),"OK - capacidade suficiente"))) -> OK - capacidade suficiente | W26: =AUX_MATRIZES!W161 -> 8508.7164
